Workbook

Sheet 1
A1: 객실판매일보 | P1: 근무자 | S1: 이정경 주간/김선우 야간/황경현 팀장 | Z1: 날짜 | AA1: 45901 | AI1: 일일영업현황보고서
A2: 일매출 | C2: =AZ72 -> 952725 | G2: 대실 | H2: =COUNTA($Z$8:$AE$67) -> 0 | M2: 숙박 | N2: =COUNTA($L$8:$O$67) -> 11 | Z2: 현금 시재 | AA2: 시작 | AB2: 371500 | AI2: 보고기준일 | AL2: ='1'!AA1 -> 45901 | AP2: 보고일자 | AS2: =AA1+1 -> 45902 | AZ2: 작성자 | BA2: =S1 -> 이정경 주간/김선우 야간/황경현 팀장
H3: =SUM(Z8:AE76)+AZ21 -> 0 | N3: =SUM(L8:O76)+AZ20 -> 952725 | AA3: 마감 | AB3: 371500
A4: 숙 박 | N4: =SUM(COUNTIF(B8:B67,{301,302,303,305,306,307,308,309,501,502,503,505,701,702,703,705,706,707,708,709})) -> 6 | O4: =SUM(COUNTIF(B8:B67,{201,202,203,205,206,207,208,209,506,507,508,509,601,602,603,605,606,607,608,609})) -> 0 | P4: 대 실 | AF4: =SUM(COUNTIF(S8:S67,{301,302,303,305,306,307,308,309,501,502,503,505,701,702,703,705,706,707,708,709})) -> 0 | AG4: =SUM(COUNTIF(S8:S67,{201,202,203,205,206,207,208,209,506,507,508,509,601,602,603,605,606,607,608,609})) -> 0
A5: 타입 | C5: C | D5: B | E5: AT | F5: AD | G5: SD | H5: ST | I5: V | J5: 특 | N5: 남은 객실 | P5: 매출보고 | R5: 현금 | S5: 계좌 | T5: 카드 | U5: 야놀자 | W5: 여기어때 | Y5: 네이버 | AA5: 부킹 | AB5: 아고다 | AC5: 익스피디아 | AD5: 트립 | AE5: 에어 | AF5: 호텔나우 | AG5: 호텔타임
A6: 잔여수량 | C6: =AL31 -> -1 | D6: =AN31 -> 3 | E6: =AP31 -> 7 | F6: =AR31 -> 1 | G6: =AS31 -> 7 | H6: =AU31 -> 4 | I6: =AW31 -> 5 | J6: =AX31 -> 0 | N6: =C6+D6+E6+F6+G6+H6+I6+J6+K6 -> 26 | P6: =C2 -> 952725 | R6: =AN14+AN15 -> 0 | S6: =AZ14+AZ15 -> 0 | T6: =AR14+AR15 -> 86000 | U6: =AS60 -> 120000 | W6: =AS61 -> 255000 | Y6: =AS62 -> 0 | AA6: =AS63 -> 0 | AB6: =AS66 -> 397800 | AC6: =AS67 -> 0 | AD6: =SUMIFS(O7:O47,C7:C47,"트립") -> 93925 | AE6: =AS65 -> 0 | AF6: =AS69 -> 0 | AG6: =AS70 -> 0
A7: 번호 | B7: 호실 | C7: 채널명 | D7: 고객명 | E7: 비고 | F7: 타입 | G7: 기간 | H7: 체크인 | I7: 체크아웃 | J7: 작성자 | K7: 비품 | L7: 현금 | M7: 카드 | N7: 계좌이체 | O7: 온라인 | P7: 번호 | Q7: 호실 | R7: 채널명 | S7: 고객명 | T7: 비고 | U7: 타입 | V7: 체크인 | W7: 체크아웃 | X7: 작성자 | Y7: 비품 | Z7: 현금 | AA7: 카드 | AB7: 계좌이체 | AE7: 온라인
A8: 1 | B8: 1210 | C8: 리뷰체험단 | D8: 김미지 | F8: AT | G8: 1 | H8: 15:00 | I8: 11:00 | J8: 이 | O8: 0 | P8: 1 | AI8: 총 매 출 | AK8: 구분 | AL8: 현금 | AP8: 카드 | AT8: 온라인 | AX8: 계좌이체 | BB8: 소계
A9: 2 | B9: 308 | C9: 아고다 | D9: 박양숙1 | F9: C | G9: 1/3 | H9: 15:00 | I9: 11:00 | J9: 이 | O9: 397800 | P9: 2 | AL9: 건수 | AN9: 금액 | AP9: 건수 | AR9: 금액 | AT9: 건수 | AV9: 금액 | AX9: 건수 | AZ9: 금액 | BB9: 건수 | BD9: 금액
A10: 3 | B10: 309 | C10: 아고다 | D10: 박양숙2 | F10: C | G10: 1/3 | H10: 15:00 | I10: 11:00 | J10: 이 | O10: 0 | P10: 3 | AK10: 숙박 | AL10: =COUNTA($L$8:$L$67) -> 0 | AN10: =SUM(L8:L67) -> 0 | AP10: =COUNT(M8:M67) -> 1 | AR10: =SUM(M8:M67) -> 80000 | AT10: =COUNTA($O$8:$O$67) -> 10 | AV10: =SUM(O8:O67) -> 866725 | AX10: =COUNTA($N$8:$N$67) -> 0 | AZ10: =SUM(N8:N67) -> 0 | BB10: =SUM(AL10+AP10+AT10+AX10) -> 11 | BD10: =SUM(AN10+AR10+AV10+AZ10) -> 946725
A11: 4 | B11: 805 | C11: 여기어때 | D11: 김봉준 | E11: C업그레이드 | F11: SD | G11: 1/2 | H11: 15:00 | I11: 11:00 | J11: 황 | K11: 2 | O11: 130000 | P11: 4 | AK11: 대실 | AL11: =COUNTA($Z$8:$Z$67) -> 0 | AN11: =SUM(Z8:Z67) -> 0 | AP11: =COUNTA($AA$8:$AA$67) -> 0 | AR11: =SUM(AA8:AA67) -> 0 | AT11: =COUNTA($AE$8:$AE$67) -> 0 | AV11: =SUM(AE8:AE67) -> 0 | AX11: =COUNTA($AB$8:$AB$68) -> 0 | AZ11: =SUM(AB8:AB67) -> 0 | BB11: =SUM(AL11+AP11+AT11+AX11) -> 0 | BD11: =SUM(AN11+AR11+AV11+AZ11) -> 0
A12: 5 | B12: 1216 | C12: 트립 | D12: ZHU/TANGXING | E12: ZHU/ZIYANG | F12: B | G12: 1 | H12: 15:00 | I12: 11:00 | J12: 김 | O12: 93925 | P12: 5 | AK12: 추가숙박 | AL12: =COUNTA($L$68:$L$76) -> 0 | AN12: =SUM(L68:L76) -> 0 | AP12: =COUNTA($M$68:$M$76) -> 0 | AR12: =SUM(M68:M76) -> 0 | AT12: =COUNTA($O$68:$O$76) -> 0 | AV12: =SUM(O68:O76) -> 0 | AX12: =COUNTA($N$68:$N$76) -> 0 | AZ12: =SUM(N68:N76) -> 0 | BB12: =SUM(AL12+AP12+AT12+AX12) -> 0 | BD12: =SUM(AN12+AR12+AV12+AZ12) -> 0
A13: 6 | C13: 현장결제 | D13: 이연순 | E13: 8/31 미결제건 | G13: 1 | H13: 15:00 | I13: 11:00 | J13: 황 | M13: 80000 | P13: 6 | AK13: 추가대실 | AL13: =COUNTA($Z$68:$Z$76) -> 0 | AN13: =SUM(Z68:Z76) -> 0 | AP13: =COUNTA($AA$68:$AA$76) -> 0 | AR13: =SUM(AA68:AA76) -> 0 | AT13: =COUNTA($AE$68:$AE$76) -> 0 | AV13: =SUM(AE68:AE76) -> 0 | AX13: =COUNTA($AB$68:$AB$76) -> 0 | AZ13: =SUM(AB68:AB76) -> 0 | BB13: =SUM(AL13+AP13+AT13+AX13) -> 0 | BD13: =SUM(AN13+AR13+AV13+AZ13) -> 0
A14: 7 | B14: 1115 | C14: 여기어때 | D14: 신철우 | E14: 특가(랜덤) | F14: AT | G14: 1 | H14: 15:00 | I14: 11:00 | J14: 황 | O14: 60000 | P14: 7 | AK14: 소계 | AL14: =SUM(AL10:AM11) -> 0 | AN14: =SUM(AN10:AO13) -> 0 | AP14: =SUM(AP10:AQ11) -> 1 | AR14: =SUM(AR10:AS13) -> 80000 | AT14: =SUM(AT10:AU11) -> 10 | AV14: =SUM(AV10:AW13) -> 866725 | AX14: =SUM(AX10:AY11) -> 0 | AZ14: =SUM(AZ10:BA13) -> 0 | BB14: =SUM(AL14+AP14+AT14+AX14) -> 11 | BD14: =SUM(BD10:BE13) -> 946725
A15: 8 | B15: 1116 | C15: 야놀자 | D15: 김혜란 | E15: 특가(랜덤) | G15: 1 | H15: 15:00 | I15: 11:00 | J15: 황 | K15: 2 | O15: 60000 | P15: 8 | AK15: 어메니티 | AL15: =AL24 -> 0 | AN15: =AN24 -> 0 | AP15: =AP24 -> 3 | AR15: =AR24 -> 6000 | AX15: =AT24 -> 0 | AZ15: =AV24 -> 0 | BB15: =AX24 -> 3 | BD15: =SUM(AN15+AR15+AV15+AZ15) -> 6000
A16: 9 | B16: 809 | C16: 여기어때 | D16: 백종훈 | F16: C | G16: 1 | H16: 15:00 | I16: 11:00 | J16: 이 | O16: 65000 | P16: 9 | BB16: 총합계 | BD16: =BD14+BD15 -> 952725
A17: 10 | B17: 902 | C17: 리뷰체험단 | D17: 오은비 | F17: SD | G17: 1 | H17: 15:00 | I17: 11:00 | J17: 이 | O17: 0 | P17: 10
A18: 11 | B18: 1114 | C18: 야놀자 | D18: 이웅재 | E18: 특가(랜덤) | F18: AT | G18: 1 | H18: 15:00 | I18: 11:00 | J18: 김 | K18: 2 | O18: 60000 | P18: 11 | AI18: 어메니티 판매현황 | AK18: 구분 | AL18: 현금 (1) | AP18: 카드 (2) | AT18: 계좌이체 (3) | AX18: 소계
A19: 12 | P19: 12 | AL19: 건수 | AN19: 금액 | AP19: 건수 | AR19: 금액 | AT19: 건수 | AV19: 금액 | AX19: 건수 | AZ19: 금액
A20: 13 | P20: 13 | AK20: 숙박 | AL20: =COUNTIF(K7:K67,1) -> 0 | AN20: =AL20*2000 -> 0 | AP20: =COUNTIF(K7:K67,2) -> 3 | AR20: =AP20*2000 -> 6000 | AT20: =COUNTIF(K8:K67,3) -> 0 | AV20: =AT20*2000 -> 0 | AX20: =SUM(AL20+AP20+AT20) -> 3 | AZ20: =SUM(AJ20+AN20+AR20+AV20) -> 6000
A21: 14 | P21: 14 | AK21: 대실 | AL21: =COUNTIF(Y7:Y67,1) -> 0 | AN21: =AL21*2000 -> 0 | AP21: =COUNTIF(Y7:Y67,2) -> 0 | AR21: =AP21*2000 -> 0 | AT21: =COUNTIF(Y8:Y67,3) -> 0 | AV21: =AT21*2000 -> 0 | AX21: =SUM(AL21+AP21+AT21) -> 0 | AZ21: =SUM(AJ21+AN21+AR21+AV21) -> 0
A22: 15 | P22: 15 | AK22: 추가 | AX22: =SUM(AL22+AP22+AT22) -> 0 | AZ22: =SUM(AJ22+AN22+AR22+AV22) -> 0
A23: 16 | P23: 16 | AX23: =SUM(AH23+AL23+AP23+AT23) -> 0 | AZ23: =SUM(AJ23+AN23+AR23+AV23) -> 0
A24: 17 | P24: 17 | AK24: 소계 | AL24: =SUM(AL20:AM23) -> 0 | AN24: =SUM(AN20:AO23) -> 0 | AP24: =SUM(AP20:AQ23) -> 3 | AR24: =SUM(AR20:AS23) -> 6000 | AT24: =SUM(AT20:AU23) -> 0 | AV24: =SUM(AV20:AW23) -> 0 | AX24: =SUM(AH24+AL24+AP24+AT24) -> 3 | AZ24: =SUM(AZ20:BA23) -> 6000
A25: 18 | P25: 18
A26: 19 | P26: 19
A27: 20 | P27: 20 | AJ27: 객실 타입 별 예약 현황
A28: 21 | P28: 21 | AJ28: 타입 | AL28: C | AN28: B | AP28: AT | AR28: AD | AS28: SD | AU28: ST | AW28: V | AX28: 특
A29: 22 | P29: 22 | AJ29: 기준수량 | AL29: 5 | AN29: 4 | AP29: 10 | AR29: 2 | AS29: 9 | AU29: 5 | AW29: 5 | AX29: 0 | AZ29: 0
A30: 23 | P30: 23 | AJ30: 예약수량 | AL30: =COUNTIF(F8:F67,"c") -> 6 | AN30: =COUNTIF(F8:F67,"b") -> 1 | AP30: =COUNTIF(F8:F67,"at") -> 3 | AR30: =COUNTIF(F8:F67,"aD") -> 1 | AS30: =COUNTIF(F8:F67,"sd") -> 2 | AU30: =COUNTIF(F8:F67,"st") -> 1 | AW30: =COUNTIF(F8:F67,"v") -> 0 | AX30: =COUNTIF(F8:F67,"PA") -> 0 | AZ30: =COUNTIF(F8:F67,"특") -> 0
A31: 24 | P31: 24 | AJ31: 잔여수량 | AL31: =AL29-AL30 -> -1 | AN31: =AN29-AN30 -> 3 | AP31: =AP29-AP30 -> 7 | AR31: =AR29-AR30 -> 1 | AS31: =AS29-AS30 -> 7 | AU31: =AU29-AU30 -> 4 | AW31: =AW29-AW30 -> 5 | AX31: =AX29-AX30 -> 0 | AZ31: =AZ29-AZ30 -> 0
A32: 25 | P32: 25 | AK32: `
A33: 26 | P33: 26
A34: 27 | P34: 27
A35: 28 | P35: 28
A36: 29 | P36: 29
A37: 30 | P37: 30
A38: 31 | P38: 31
A39: 32 | P39: 32
A40: 33 | P40: 33
...

Sheet 2
A1: 객실판매일보 | P1: 근무자 | S1: 양동근 대체 / 김선우 야간 / 황경현 팀장 | Z1: 날짜 | AA1: 45902 | AI1: 일일영업현황보고서
A2: 일매출 | C2: =AZ72 -> 929000 | G2: 대실 | H2: =COUNTA($Z$8:$AE$67) -> 0 | M2: 숙박 | N2: =COUNTA($L$8:$O$67) -> 19 | Z2: 현금 시재 | AA2: 시작 | AB2: 371500 | AI2: 보고기준일 | AL2: ='2'!AA1 -> 45902 | AP2: 보고일자 | AS2: =AA1+1 -> 45903 | AZ2: 작성자 | BA2: =S1 -> 양동근 대체 / 김선우 야간 / 황경현 팀장
H3: =SUM(Z8:AE76)+AZ21 -> 0 | N3: =SUM(L8:O76)+AZ20 -> 929000 | AA3: 마감 | AB3: 371500
A4: 숙 박 | N4: =SUM(COUNTIF(B8:B67,{301,302,303,305,306,307,308,309,501,502,503,505,701,702,703,705,706,707,708,709})) -> 7 | O4: =SUM(COUNTIF(B8:B67,{201,202,203,205,206,207,208,209,506,507,508,509,601,602,603,605,606,607,608,609})) -> 0 | P4: 대 실 | AF4: =SUM(COUNTIF(S8:S67,{301,302,303,305,306,307,308,309,501,502,503,505,701,702,703,705,706,707,708,709})) -> 0 | AG4: =SUM(COUNTIF(S8:S67,{201,202,203,205,206,207,208,209,506,507,508,509,601,602,603,605,606,607,608,609})) -> 0
A5: 타입 | C5: C | D5: B | E5: AT | F5: AD | G5: SD | H5: ST | I5: V | J5: 특 | N5: 남은 객실 | P5: 매출보고 | R5: 현금 | S5: 계좌 | T5: 카드 | U5: 야놀자 | W5: 여기어때 | Y5: 네이버 | AA5: 부킹 | AB5: 아고다 | AC5: 익스피디아 | AD5: 트립 | AE5: 에어 | AF5: 호텔나우 | AG5: 호텔타임
A6: 잔여수량 | C6: =AL31 -> 0 | D6: =AN31 -> 4 | E6: =AP31 -> 7 | F6: =AR31 -> 1 | G6: =AS31 -> 3 | H6: =AU31 -> 4 | I6: =AW31 -> 3 | J6: =AX31 -> 0 | N6: =C6+D6+E6+F6+G6+H6+I6+J6+K6 -> 22 | P6: =C2 -> 929000 | R6: =AN14+AN15 -> 0 | S6: =AZ14+AZ15 -> 0 | T6: =AR14+AR15 -> 4000 | U6: =AS60 -> 285000 | W6: =AS61 -> 575000 | Y6: =AS62 -> 65000 | AA6: =AS63 -> 0 | AB6: =AS66 -> 0 | AC6: =AS67 -> 0 | AD6: =SUMIFS(O7:O47,C7:C47,"트립") -> 0 | AE6: =AS65 -> 0 | AF6: =AS69 -> 0 | AG6: =AS70 -> 0
A7: 번호 | B7: 호실 | C7: 채널명 | D7: 고객명 | E7: 비고 | F7: 타입 | G7: 기간 | H7: 체크인 | I7: 체크아웃 | J7: 작성자 | K7: 비품 | L7: 현금 | M7: 카드 | N7: 계좌이체 | O7: 온라인 | P7: 번호 | Q7: 호실 | R7: 채널명 | S7: 고객명 | T7: 비고 | U7: 타입 | V7: 체크인 | W7: 체크아웃 | X7: 작성자 | Y7: 비품 | Z7: 현금 | AA7: 카드 | AB7: 계좌이체 | AE7: 온라인
A8: 1 | B8: 303 | C8: 야놀자 | D8: 김은기 | E8: 특가(랜덤) | F8: C | G8: 1 | H8: 15:00 | I8: 11:00 | J8: 이 | O8: 60000 | P8: 1 | AI8: 총 매 출 | AK8: 구분 | AL8: 현금 | AP8: 카드 | AT8: 온라인 | AX8: 계좌이체 | BB8: 소계
A9: 2 | B9: 907 | C9: 네이버 | D9: 정창원 | E9: C업그레이드 | F9: SD | G9: 1 | H9: 15:00 | I9: 11:00 | J9: 양 | O9: 65000 | P9: 2 | AL9: 건수 | AN9: 금액 | AP9: 건수 | AR9: 금액 | AT9: 건수 | AV9: 금액 | AX9: 건수 | AZ9: 금액 | BB9: 건수 | BD9: 금액
A10: 3 | B10: 1004 | C10: 여기어때 | D10: 김선우 | E10: C업그레이드 | F10: SD | G10: 1 | H10: 15:00 | I10: 11:00 | J10: 황 | O10: 65000 | P10: 3 | AK10: 숙박 | AL10: =COUNTA($L$8:$L$67) -> 0 | AN10: =SUM(L8:L67) -> 0 | AP10: =COUNT(M8:M67) -> 0 | AR10: =SUM(M8:M67) -> 0 | AT10: =COUNTA($O$8:$O$67) -> 19 | AV10: =SUM(O8:O67) -> 925000 | AX10: =COUNTA($N$8:$N$67) -> 0 | AZ10: =SUM(N8:N67) -> 0 | BB10: =SUM(AL10+AP10+AT10+AX10) -> 19 | BD10: =SUM(AN10+AR10+AV10+AZ10) -> 925000
A11: 4 | B11: 1206 | C11: 여기어때 | D11: 박현수 | F11: AD | G11: 1 | H11: 15:00 | I11: 11:00 | J11: 황 | K11: 2 | O11: 70000 | P11: 4 | AK11: 대실 | AL11: =COUNTA($Z$8:$Z$67) -> 0 | AN11: =SUM(Z8:Z67) -> 0 | AP11: =COUNTA($AA$8:$AA$67) -> 0 | AR11: =SUM(AA8:AA67) -> 0 | AT11: =COUNTA($AE$8:$AE$67) -> 0 | AV11: =SUM(AE8:AE67) -> 0 | AX11: =COUNTA($AB$8:$AB$68) -> 0 | AZ11: =SUM(AB8:AB67) -> 0 | BB11: =SUM(AL11+AP11+AT11+AX11) -> 0 | BD11: =SUM(AN11+AR11+AV11+AZ11) -> 0
A12: 5 | B12: 1107 | C12: 야놀자 | D12: 박효찬 | E12: C업그레이드 | F12: SD | G12: 1 | H12: 15:00 | I12: 11:00 | J12: 황 | O12: 65000 | P12: 5 | AK12: 추가숙박 | AL12: =COUNTA($L$68:$L$76) -> 0 | AN12: =SUM(L68:L76) -> 0 | AP12: =COUNTA($M$68:$M$76) -> 0 | AR12: =SUM(M68:M76) -> 0 | AT12: =COUNTA($O$68:$O$76) -> 0 | AV12: =SUM(O68:O76) -> 0 | AX12: =COUNTA($N$68:$N$76) -> 0 | AZ12: =SUM(N68:N76) -> 0 | BB12: =SUM(AL12+AP12+AT12+AX12) -> 0 | BD12: =SUM(AN12+AR12+AV12+AZ12) -> 0
A13: 6 | B13: 307 | C13: 여기어때 | D13: 백종훈 | F13: C | G13: 1 | H13: 15:00 | I13: 11:00 | J13: 황 | O13: 65000 | P13: 6 | AK13: 추가대실 | AL13: =COUNTA($Z$68:$Z$76) -> 0 | AN13: =SUM(Z68:Z76) -> 0 | AP13: =COUNTA($AA$68:$AA$76) -> 0 | AR13: =SUM(AA68:AA76) -> 0 | AT13: =COUNTA($AE$68:$AE$76) -> 0 | AV13: =SUM(AE68:AE76) -> 0 | AX13: =COUNTA($AB$68:$AB$76) -> 0 | AZ13: =SUM(AB68:AB76) -> 0 | BB13: =SUM(AL13+AP13+AT13+AX13) -> 0 | BD13: =SUM(AN13+AR13+AV13+AZ13) -> 0
A14: 7 | B14: 1214 | C14: 여기어때 | D14: 장서준 | E14: 특가(랜덤) | F14: AT | G14: 1 | H14: 15:00 | I14: 11:00 | J14: 황 | O14: 60000 | P14: 7 | AK14: 소계 | AL14: =SUM(AL10:AM11) -> 0 | AN14: =SUM(AN10:AO13) -> 0 | AP14: =SUM(AP10:AQ11) -> 0 | AR14: =SUM(AR10:AS13) -> 0 | AT14: =SUM(AT10:AU11) -> 19 | AV14: =SUM(AV10:AW13) -> 925000 | AX14: =SUM(AX10:AY11) -> 0 | AZ14: =SUM(AZ10:BA13) -> 0 | BB14: =SUM(AL14+AP14+AT14+AX14) -> 19 | BD14: =SUM(BD10:BE13) -> 925000
A15: 8 | B15: 902 | C15: 여기어때 | D15: 정주경 | E15: C업그레이드 | F15: SD | G15: 1 | H15: 15:00 | I15: 11:00 | J15: 양 | O15: 65000 | P15: 8 | AK15: 어메니티 | AL15: =AL24 -> 0 | AN15: =AN24 -> 0 | AP15: =AP24 -> 2 | AR15: =AR24 -> 4000 | AX15: =AT24 -> 0 | AZ15: =AV24 -> 0 | BB15: =AX24 -> 2 | BD15: =SUM(AN15+AR15+AV15+AZ15) -> 4000
A16: 9 | B16: 701 | C16: 야놀자 | D16: 김진우1 | F16: V | G16: 1 | H16: 15:00 | I16: 11:00 | J16: 양 | O16: 80000 | P16: 9 | BB16: 총합계 | BD16: =BD14+BD15 -> 929000
A17: 10 | B17: 1110 | C17: 야놀자 | D17: 김진우2 | F17: V | G17: 1 | H17: 15:00 | I17: 11:00 | J17: 양 | O17: 80000 | P17: 10
A18: 11 | B18: 1111 | C18: 여기어때 | D18: 조윤희 | E18: 특가(랜덤) | G18: 1 | H18: 15:00 | I18: 11:00 | J18: 김 | O18: 60000 | P18: 11 | AI18: 어메니티 판매현황 | AK18: 구분 | AL18: 현금 (1) | AP18: 카드 (2) | AT18: 계좌이체 (3) | AX18: 소계
A19: 12 | B19: 809 | C19: 여기어때 | D19: 나승재 | E19: C업그레이드 | F19: SD | G19: 1 | H19: 15:00 | I19: 11:00 | J19: 김 | O19: 65000 | P19: 12 | AL19: 건수 | AN19: 금액 | AP19: 건수 | AR19: 금액 | AT19: 건수 | AV19: 금액 | AX19: 건수 | AZ19: 금액
A20: 13 | B20: 1115 | C20: 여기어때 | D20: 강민진 | E20: 특가(랜덤) | F20: AT | G20: 1 | H20: 15:00 | I20: 11:00 | J20: 김 | O20: 60000 | P20: 13 | AK20: 숙박 | AL20: =COUNTIF(K7:K67,1) -> 0 | AN20: =AL20*2000 -> 0 | AP20: =COUNTIF(K7:K67,2) -> 2 | AR20: =AP20*2000 -> 4000 | AT20: =COUNTIF(K8:K67,3) -> 0 | AV20: =AT20*2000 -> 0 | AX20: =SUM(AL20+AP20+AT20) -> 2 | AZ20: =SUM(AJ20+AN20+AR20+AV20) -> 4000
A21: 14 | B21: 1215 | C21: 여기어때 | D21: 홍석진 | E21: B업그레이드 | F21: AT | G21: 1 | H21: 15:00 | I21: 11:00 | J21: 김 | K21: 2 | O21: 65000 | P21: 14 | AK21: 대실 | AL21: =COUNTIF(Y7:Y67,1) -> 0 | AN21: =AL21*2000 -> 0 | AP21: =COUNTIF(Y7:Y67,2) -> 0 | AR21: =AP21*2000 -> 0 | AT21: =COUNTIF(Y8:Y67,3) -> 0 | AV21: =AT21*2000 -> 0 | AX21: =SUM(AL21+AP21+AT21) -> 0 | AZ21: =SUM(AJ21+AN21+AR21+AV21) -> 0
A22: 15 | P22: 15 | AK22: 추가 | AX22: =SUM(AL22+AP22+AT22) -> 0 | AZ22: =SUM(AJ22+AN22+AR22+AV22) -> 0
A23: 16 | P23: 16 | AX23: =SUM(AH23+AL23+AP23+AT23) -> 0 | AZ23: =SUM(AJ23+AN23+AR23+AV23) -> 0
A24: 17 | P24: 17 | AK24: 소계 | AL24: =SUM(AL20:AM23) -> 0 | AN24: =SUM(AN20:AO23) -> 0 | AP24: =SUM(AP20:AQ23) -> 2 | AR24: =SUM(AR20:AS23) -> 4000 | AT24: =SUM(AT20:AU23) -> 0 | AV24: =SUM(AV20:AW23) -> 0 | AX24: =SUM(AH24+AL24+AP24+AT24) -> 2 | AZ24: =SUM(AZ20:BA23) -> 4000
A25: 18 | P25: 18
A26: 19 | P26: 19
A27: 20 | P27: 20 | AJ27: 객실 타입 별 예약 현황
A28: 21 | P28: 21 | AJ28: 타입 | AL28: C | AN28: B | AP28: AT | AR28: AD | AS28: SD | AU28: ST | AW28: V | AX28: 특
A29: 22 | P29: 22 | AJ29: 기준수량 | AL29: 5 | AN29: 4 | AP29: 10 | AR29: 2 | AS29: 9 | AU29: 5 | AW29: 5 | AX29: 0 | AZ29: 0
A30: 23 | P30: 23 | AJ30: 예약수량 | AL30: =COUNTIF(F8:F67,"c") -> 5 | AN30: =COUNTIF(F8:F67,"b") -> 0 | AP30: =COUNTIF(F8:F67,"at") -> 3 | AR30: =COUNTIF(F8:F67,"aD") -> 1 | AS30: =COUNTIF(F8:F67,"sd") -> 6 | AU30: =COUNTIF(F8:F67,"st") -> 1 | AW30: =COUNTIF(F8:F67,"v") -> 2 | AX30: =COUNTIF(F8:F67,"PA") -> 0 | AZ30: =COUNTIF(F8:F67,"특") -> 0
A31: 24 | P31: 24 | AJ31: 잔여수량 | AL31: =AL29-AL30 -> 0 | AN31: =AN29-AN30 -> 4 | AP31: =AP29-AP30 -> 7 | AR31: =AR29-AR30 -> 1 | AS31: =AS29-AS30 -> 3 | AU31: =AU29-AU30 -> 4 | AW31: =AW29-AW30 -> 3 | AX31: =AX29-AX30 -> 0 | AZ31: =AZ29-AZ30 -> 0
A32: 25 | P32: 25 | AK32: `
A33: 26 | P33: 26
A34: 27 | P34: 27
A35: 28 | P35: 28
A36: 29 | P36: 29
A37: 30 | P37: 30
A38: 31 | P38: 31
A39: 32 | P39: 32
A40: 33 | P40: 33
...

Sheet 3
A1: 객실판매일보 | P1: 근무자 | S1: 이정경 주간/양동건 대체/황경현 팀장 | Z1: 날짜 | AA1: 45903 | AI1: 일일영업현황보고서
A2: 일매출 | C2: =AZ72 -> 709000 | G2: 대실 | H2: =COUNTA($Z$8:$AE$67) -> 0 | M2: 숙박 | N2: =COUNTA($L$8:$O$67) -> 15 | Z2: 현금 시재 | AA2: 시작 | AB2: 371500 | AI2: 보고기준일 | AL2: ='3'!AA1 -> 45903 | AP2: 보고일자 | AS2: =AA1+1 -> 45904 | AZ2: 작성자 | BA2: =S1 -> 이정경 주간/양동건 대체/황경현 팀장
H3: =SUM(Z8:AE76)+AZ21 -> 0 | N3: =SUM(L8:O76)+AZ20 -> 709000 | AA3: 마감 | AB3: 371500
A4: 숙 박 | N4: =SUM(COUNTIF(B8:B67,{301,302,303,305,306,307,308,309,501,502,503,505,701,702,703,705,706,707,708,709})) -> 6 | O4: =SUM(COUNTIF(B8:B67,{201,202,203,205,206,207,208,209,506,507,508,509,601,602,603,605,606,607,608,609})) -> 0 | P4: 대 실 | AF4: =SUM(COUNTIF(S8:S67,{301,302,303,305,306,307,308,309,501,502,503,505,701,702,703,705,706,707,708,709})) -> 0 | AG4: =SUM(COUNTIF(S8:S67,{201,202,203,205,206,207,208,209,506,507,508,509,601,602,603,605,606,607,608,609})) -> 0
A5: 타입 | C5: C | D5: B | E5: AT | F5: AD | G5: SD | H5: ST | I5: V | J5: 특 | N5: 남은 객실 | P5: 매출보고 | R5: 현금 | S5: 계좌 | T5: 카드 | U5: 야놀자 | W5: 여기어때 | Y5: 네이버 | AA5: 부킹 | AB5: 아고다 | AC5: 익스피디아 | AD5: 트립 | AE5: 에어 | AF5: 호텔나우 | AG5: 호텔타임
A6: 잔여수량 | C6: =AL31 -> 0 | D6: =AN31 -> 1 | E6: =AP31 -> 9 | F6: =AR31 -> 1 | G6: =AS31 -> 6 | H6: =AU31 -> 4 | I6: =AW31 -> 4 | J6: =AX31 -> 0 | N6: =C6+D6+E6+F6+G6+H6+I6+J6+K6 -> 25 | P6: =C2 -> 709000 | R6: =AN14+AN15 -> 0 | S6: =AZ14+AZ15 -> 0 | T6: =AR14+AR15 -> 4000 | U6: =AS60 -> 260000 | W6: =AS61 -> 445000 | Y6: =AS62 -> 0 | AA6: =AS63 -> 0 | AB6: =AS66 -> 0 | AC6: =AS67 -> 0 | AD6: =SUMIFS(O7:O47,C7:C47,"트립") -> 0 | AE6: =AS65 -> 0 | AF6: =AS69 -> 0 | AG6: =AS70 -> 0
A7: 번호 | B7: 호실 | C7: 채널명 | D7: 고객명 | E7: 비고 | F7: 타입 | G7: 기간 | H7: 체크인 | I7: 체크아웃 | J7: 작성자 | K7: 비품 | L7: 현금 | M7: 카드 | N7: 계좌이체 | O7: 온라인 | P7: 번호 | Q7: 호실 | R7: 채널명 | S7: 고객명 | T7: 비고 | U7: 타입 | V7: 체크인 | W7: 체크아웃 | X7: 작성자 | Y7: 비품 | Z7: 현금 | AA7: 카드 | AB7: 계좌이체 | AE7: 온라인
A8: 1 | B8: 811 | C8: 야놀자 | D8: 류민철 | E8: 특가(랜덤) | F8: B | G8: 1 | H8: 15:00 | I8: 11:00 | O8: 60000 | P8: 1 | AI8: 총 매 출 | AK8: 구분 | AL8: 현금 | AP8: 카드 | AT8: 온라인 | AX8: 계좌이체 | BB8: 소계
A9: 2 | B9: 902 | C9: 체험단 | D9: 송주은 | E9: 무료 | F9: SD | G9: 1 | H9: 15:00 | I9: 11:00 | J9: 이 | O9: 0 | P9: 2 | AL9: 건수 | AN9: 금액 | AP9: 건수 | AR9: 금액 | AT9: 건수 | AV9: 금액 | AX9: 건수 | AZ9: 금액 | BB9: 건수 | BD9: 금액
A10: 3 | B10: 1111 | C10: 여기어때 | D10: 윤현선 | E10: 특가(랜덤) | F10: B | G10: 1 | H10: 15:00 | I10: 11:00 | J10: 이 | K10: 2 | O10: 60000 | P10: 3 | AK10: 숙박 | AL10: =COUNTA($L$8:$L$67) -> 0 | AN10: =SUM(L8:L67) -> 0 | AP10: =COUNT(M8:M67) -> 0 | AR10: =SUM(M8:M67) -> 0 | AT10: =COUNTA($O$8:$O$67) -> 15 | AV10: =SUM(O8:O67) -> 705000 | AX10: =COUNTA($N$8:$N$67) -> 0 | AZ10: =SUM(N8:N67) -> 0 | BB10: =SUM(AL10+AP10+AT10+AX10) -> 15 | BD10: =SUM(AN10+AR10+AV10+AZ10) -> 705000
A11: 4 | B11: 911 | C11: 여기어때 | D11: 홍성빈 | F11: B | G11: 1/2 | H11: 15:00 | I11: 11:00 | J11: 양 | O11: 130000 | P11: 4 | AK11: 대실 | AL11: =COUNTA($Z$8:$Z$67) -> 0 | AN11: =SUM(Z8:Z67) -> 0 | AP11: =COUNTA($AA$8:$AA$67) -> 0 | AR11: =SUM(AA8:AA67) -> 0 | AT11: =COUNTA($AE$8:$AE$67) -> 0 | AV11: =SUM(AE8:AE67) -> 0 | AX11: =COUNTA($AB$8:$AB$68) -> 0 | AZ11: =SUM(AB8:AB67) -> 0 | BB11: =SUM(AL11+AP11+AT11+AX11) -> 0 | BD11: =SUM(AN11+AR11+AV11+AZ11) -> 0
A12: 5 | B12: 805 | C12: 여기어때 | D12: 백종훈 | E12: C업그레이드 | F12: SD | G12: 1 | H12: 15:00 | I12: 11:00 | J12: 이 | O12: 65000 | P12: 5 | AK12: 추가숙박 | AL12: =COUNTA($L$68:$L$76) -> 0 | AN12: =SUM(L68:L76) -> 0 | AP12: =COUNTA($M$68:$M$76) -> 0 | AR12: =SUM(M68:M76) -> 0 | AT12: =COUNTA($O$68:$O$76) -> 0 | AV12: =SUM(O68:O76) -> 0 | AX12: =COUNTA($N$68:$N$76) -> 0 | AZ12: =SUM(N68:N76) -> 0 | BB12: =SUM(AL12+AP12+AT12+AX12) -> 0 | BD12: =SUM(AN12+AR12+AV12+AZ12) -> 0
A13: 6 | B13: 1216 | C13: 여기어때 | D13: 미고사 | E13: 특가(랜덤) | F13: AT | G13: 1 | H13: 15:00 | I13: 11:00 | J13: 이 | O13: 60000 | P13: 6 | AK13: 추가대실 | AL13: =COUNTA($Z$68:$Z$76) -> 0 | AN13: =SUM(Z68:Z76) -> 0 | AP13: =COUNTA($AA$68:$AA$76) -> 0 | AR13: =SUM(AA68:AA76) -> 0 | AT13: =COUNTA($AE$68:$AE$76) -> 0 | AV13: =SUM(AE68:AE76) -> 0 | AX13: =COUNTA($AB$68:$AB$76) -> 0 | AZ13: =SUM(AB68:AB76) -> 0 | BB13: =SUM(AL13+AP13+AT13+AX13) -> 0 | BD13: =SUM(AN13+AR13+AV13+AZ13) -> 0
A14: 7 | B14: 303 | C14: 여기어때 | D14: 이동욱 | E14: 특가(랜덤) | F14: C | G14: 1 | H14: 15:00 | I14: 11:00 | J14: 이 | O14: 60000 | P14: 7 | AK14: 소계 | AL14: =SUM(AL10:AM11) -> 0 | AN14: =SUM(AN10:AO13) -> 0 | AP14: =SUM(AP10:AQ11) -> 0 | AR14: =SUM(AR10:AS13) -> 0 | AT14: =SUM(AT10:AU11) -> 15 | AV14: =SUM(AV10:AW13) -> 705000 | AX14: =SUM(AX10:AY11) -> 0 | AZ14: =SUM(AZ10:BA13) -> 0 | BB14: =SUM(AL14+AP14+AT14+AX14) -> 15 | BD14: =SUM(BD10:BE13) -> 705000
A15: 8 | B15: 1210 | C15: 야놀자 | D15: 정우진 | F15: V | G15: 1 | H15: 15:00 | I15: 11:00 | J15: 이 | O15: 80000 | P15: 8 | AK15: 어메니티 | AL15: =AL24 -> 0 | AN15: =AN24 -> 0 | AP15: =AP24 -> 2 | AR15: =AR24 -> 4000 | AX15: =AT24 -> 0 | AZ15: =AV24 -> 0 | BB15: =AX24 -> 2 | BD15: =SUM(AN15+AR15+AV15+AZ15) -> 4000
A16: 9 | B16: 307 | C16: 야놀자 | D16: 우다현 | E16: 특가(랜덤) | F16: C | G16: 1 | H16: 15:00 | I16: 11:00 | J16: 이 | O16: 60000 | P16: 9 | BB16: 총합계 | BD16: =BD14+BD15 -> 709000
A17: 10 | B17: 809 | C17: 야놀자 | D17: 최홍석 | E17: 특가(랜덤) | F17: SD | G17: 1 | H17: 15:00 | I17: 11:00 | J17: 이 | O17: 60000 | P17: 10
A18: 11 | B18: 1105 | C18: 여기어때 | D18: 홍석진 | F18: AD | G18: 1 | H18: 15:00 | I18: 11:00 | J18: 이 | K18: 2 | O18: 70000 | P18: 11 | AI18: 어메니티 판매현황 | AK18: 구분 | AL18: 현금 (1) | AP18: 카드 (2) | AT18: 계좌이체 (3) | AX18: 소계
A19: 12 | P19: 12 | AL19: 건수 | AN19: 금액 | AP19: 건수 | AR19: 금액 | AT19: 건수 | AV19: 금액 | AX19: 건수 | AZ19: 금액
A20: 13 | P20: 13 | AK20: 숙박 | AL20: =COUNTIF(K7:K67,1) -> 0 | AN20: =AL20*2000 -> 0 | AP20: =COUNTIF(K7:K67,2) -> 2 | AR20: =AP20*2000 -> 4000 | AT20: =COUNTIF(K8:K67,3) -> 0 | AV20: =AT20*2000 -> 0 | AX20: =SUM(AL20+AP20+AT20) -> 2 | AZ20: =SUM(AJ20+AN20+AR20+AV20) -> 4000
A21: 14 | P21: 14 | AK21: 대실 | AL21: =COUNTIF(Y7:Y67,1) -> 0 | AN21: =AL21*2000 -> 0 | AP21: =COUNTIF(Y7:Y67,2) -> 0 | AR21: =AP21*2000 -> 0 | AT21: =COUNTIF(Y8:Y67,3) -> 0 | AV21: =AT21*2000 -> 0 | AX21: =SUM(AL21+AP21+AT21) -> 0 | AZ21: =SUM(AJ21+AN21+AR21+AV21) -> 0
A22: 15 | P22: 15 | AK22: 추가 | AX22: =SUM(AL22+AP22+AT22) -> 0 | AZ22: =SUM(AJ22+AN22+AR22+AV22) -> 0
A23: 16 | P23: 16 | AX23: =SUM(AH23+AL23+AP23+AT23) -> 0 | AZ23: =SUM(AJ23+AN23+AR23+AV23) -> 0
A24: 17 | P24: 17 | AK24: 소계 | AL24: =SUM(AL20:AM23) -> 0 | AN24: =SUM(AN20:AO23) -> 0 | AP24: =SUM(AP20:AQ23) -> 2 | AR24: =SUM(AR20:AS23) -> 4000 | AT24: =SUM(AT20:AU23) -> 0 | AV24: =SUM(AV20:AW23) -> 0 | AX24: =SUM(AH24+AL24+AP24+AT24) -> 2 | AZ24: =SUM(AZ20:BA23) -> 4000
A25: 18 | P25: 18
A26: 19 | P26: 19
A27: 20 | P27: 20 | AJ27: 객실 타입 별 예약 현황
A28: 21 | P28: 21 | AJ28: 타입 | AL28: C | AN28: B | AP28: AT | AR28: AD | AS28: SD | AU28: ST | AW28: V | AX28: 특
A29: 22 | P29: 22 | AJ29: 기준수량 | AL29: 5 | AN29: 4 | AP29: 10 | AR29: 2 | AS29: 9 | AU29: 5 | AW29: 5 | AX29: 0 | AZ29: 0
A30: 23 | P30: 23 | AJ30: 예약수량 | AL30: =COUNTIF(F8:F67,"c") -> 5 | AN30: =COUNTIF(F8:F67,"b") -> 3 | AP30: =COUNTIF(F8:F67,"at") -> 1 | AR30: =COUNTIF(F8:F67,"aD") -> 1 | AS30: =COUNTIF(F8:F67,"sd") -> 3 | AU30: =COUNTIF(F8:F67,"st") -> 1 | AW30: =COUNTIF(F8:F67,"v") -> 1 | AX30: =COUNTIF(F8:F67,"PA") -> 0 | AZ30: =COUNTIF(F8:F67,"특") -> 0
A31: 24 | P31: 24 | AJ31: 잔여수량 | AL31: =AL29-AL30 -> 0 | AN31: =AN29-AN30 -> 1 | AP31: =AP29-AP30 -> 9 | AR31: =AR29-AR30 -> 1 | AS31: =AS29-AS30 -> 6 | AU31: =AU29-AU30 -> 4 | AW31: =AW29-AW30 -> 4 | AX31: =AX29-AX30 -> 0 | AZ31: =AZ29-AZ30 -> 0
A32: 25 | P32: 25 | AK32: `
A33: 26 | P33: 26
A34: 27 | P34: 27
A35: 28 | P35: 28
A36: 29 | P36: 29
A37: 30 | P37: 30
A38: 31 | P38: 31
A39: 32 | P39: 32
A40: 33 | P40: 33
...

Sheet 4
A1: 객실판매일보 | P1: 근무자 | S1: 이정경 주간/양동건 대체/김선우 야간 | Z1: 날짜 | AA1: 45904 | AI1: 일일영업현황보고서
A2: 일매출 | C2: =AZ72 -> 625300 | G2: 대실 | H2: =COUNTA($Z$8:$AE$67) -> 0 | M2: 숙박 | N2: =COUNTA($L$8:$O$67) -> 12 | Z2: 현금 시재 | AA2: 시작 | AB2: 371500 | AI2: 보고기준일 | AL2: ='4'!AA1 -> 45904 | AP2: 보고일자 | AS2: =AA1+1 -> 45905 | AZ2: 작성자 | BA2: =S1 -> 이정경 주간/양동건 대체/김선우 야간
H3: =SUM(Z8:AE76)+AZ21 -> 0 | N3: =SUM(L8:O76)+AZ20 -> 625300 | AA3: 마감 | AB3: 371500
A4: 숙 박 | N4: =SUM(COUNTIF(B8:B67,{301,302,303,305,306,307,308,309,501,502,503,505,701,702,703,705,706,707,708,709})) -> 5 | O4: =SUM(COUNTIF(B8:B67,{201,202,203,205,206,207,208,209,506,507,508,509,601,602,603,605,606,607,608,609})) -> 0 | P4: 대 실 | AF4: =SUM(COUNTIF(S8:S67,{301,302,303,305,306,307,308,309,501,502,503,505,701,702,703,705,706,707,708,709})) -> 0 | AG4: =SUM(COUNTIF(S8:S67,{201,202,203,205,206,207,208,209,506,507,508,509,601,602,603,605,606,607,608,609})) -> 0
A5: 타입 | C5: C | D5: B | E5: AT | F5: AD | G5: SD | H5: ST | I5: V | J5: 특 | N5: 남은 객실 | P5: 매출보고 | R5: 현금 | S5: 계좌 | T5: 카드 | U5: 야놀자 | W5: 여기어때 | Y5: 네이버 | AA5: 부킹 | AB5: 아고다 | AC5: 익스피디아 | AD5: 트립 | AE5: 에어 | AF5: 호텔나우 | AG5: 호텔타임
A6: 잔여수량 | C6: =AL31 -> 1 | D6: =AN31 -> 2 | E6: =AP31 -> 8 | F6: =AR31 -> 2 | G6: =AS31 -> 8 | H6: =AU31 -> 4 | I6: =AW31 -> 3 | J6: =AX31 -> 0 | N6: =C6+D6+E6+F6+G6+H6+I6+J6+K6 -> 28 | P6: =C2 -> 625300 | R6: =AN14+AN15 -> 0 | S6: =AZ14+AZ15 -> 0 | T6: =AR14+AR15 -> 4000 | U6: =AS60 -> 280000 | W6: =AS61 -> 275000 | Y6: =AS62 -> 0 | AA6: =AS63 -> 0 | AB6: =AS66 -> 66300 | AC6: =AS67 -> 0 | AD6: =SUMIFS(O7:O47,C7:C47,"트립") -> 0 | AE6: =AS65 -> 0 | AF6: =AS69 -> 0 | AG6: =AS70 -> 0
A7: 번호 | B7: 호실 | C7: 채널명 | D7: 고객명 | E7: 비고 | F7: 타입 | G7: 기간 | H7: 체크인 | I7: 체크아웃 | J7: 작성자 | K7: 비품 | L7: 현금 | M7: 카드 | N7: 계좌이체 | O7: 온라인 | P7: 번호 | Q7: 호실 | R7: 채널명 | S7: 고객명 | T7: 비고 | U7: 타입 | V7: 체크인 | W7: 체크아웃 | X7: 작성자 | Y7: 비품 | Z7: 현금 | AA7: 카드 | AB7: 계좌이체 | AE7: 온라인
A8: 1 | B8: 907 | C8: 리뷰체험단 | D8: 방지은 | F8: SD | G8: 1 | H8: 15:00 | I8: 11:00 | J8: 김 | O8: 0 | P8: 1 | AI8: 총 매 출 | AK8: 구분 | AL8: 현금 | AP8: 카드 | AT8: 온라인 | AX8: 계좌이체 | BB8: 소계
A9: 2 | B9: 1110 | C9: 야놀자 | D9: 전상훈 | F9: V | G9: 1 | H9: 15:00 | I9: 11:00 | J9: 김 | O9: 80000 | P9: 2 | AL9: 건수 | AN9: 금액 | AP9: 건수 | AR9: 금액 | AT9: 건수 | AV9: 금액 | AX9: 건수 | AZ9: 금액 | BB9: 건수 | BD9: 금액
A10: 3 | B10: 1011 | C10: 여기어때 | D10: 전경민 | F10: B | G10: 1/2 | H10: 15:00 | I10: 11:00 | J10: 양 | K10: 2 | O10: 150000 | P10: 3 | AK10: 숙박 | AL10: =COUNTA($L$8:$L$67) -> 0 | AN10: =SUM(L8:L67) -> 0 | AP10: =COUNT(M8:M67) -> 0 | AR10: =SUM(M8:M67) -> 0 | AT10: =COUNTA($O$8:$O$67) -> 12 | AV10: =SUM(O8:O67) -> 621300 | AX10: =COUNTA($N$8:$N$67) -> 0 | AZ10: =SUM(N8:N67) -> 0 | BB10: =SUM(AL10+AP10+AT10+AX10) -> 12 | BD10: =SUM(AN10+AR10+AV10+AZ10) -> 621300
A11: 4 | B11: 303 | C11: 야놀자 | D11: 김영훈 | E11: 특가(랜덤) | F11: C | G11: 1 | H11: 15:00 | I11: 11:00 | J11: 이 | O11: 60000 | P11: 4 | AK11: 대실 | AL11: =COUNTA($Z$8:$Z$67) -> 0 | AN11: =SUM(Z8:Z67) -> 0 | AP11: =COUNTA($AA$8:$AA$67) -> 0 | AR11: =SUM(AA8:AA67) -> 0 | AT11: =COUNTA($AE$8:$AE$67) -> 0 | AV11: =SUM(AE8:AE67) -> 0 | AX11: =COUNTA($AB$8:$AB$68) -> 0 | AZ11: =SUM(AB8:AB67) -> 0 | BB11: =SUM(AL11+AP11+AT11+AX11) -> 0 | BD11: =SUM(AN11+AR11+AV11+AZ11) -> 0
A12: 5 | B12: 1210 | C12: 야놀자 | D12: 정우진 | F12: V | G12: 1 | H12: 15:00 | I12: 11:00 | J12: 이 | O12: 80000 | P12: 5 | AK12: 추가숙박 | AL12: =COUNTA($L$68:$L$76) -> 0 | AN12: =SUM(L68:L76) -> 0 | AP12: =COUNTA($M$68:$M$76) -> 0 | AR12: =SUM(M68:M76) -> 0 | AT12: =COUNTA($O$68:$O$76) -> 0 | AV12: =SUM(O68:O76) -> 0 | AX12: =COUNTA($N$68:$N$76) -> 0 | AZ12: =SUM(N68:N76) -> 0 | BB12: =SUM(AL12+AP12+AT12+AX12) -> 0 | BD12: =SUM(AN12+AR12+AV12+AZ12) -> 0
A13: 6 | B13: 309 | C13: 아고다 | D13: 유자은 | F13: C | G13: 1 | H13: 15:00 | I13: 11:00 | J13: 이 | O13: 66300 | P13: 6 | AK13: 추가대실 | AL13: =COUNTA($Z$68:$Z$76) -> 0 | AN13: =SUM(Z68:Z76) -> 0 | AP13: =COUNTA($AA$68:$AA$76) -> 0 | AR13: =SUM(AA68:AA76) -> 0 | AT13: =COUNTA($AE$68:$AE$76) -> 0 | AV13: =SUM(AE68:AE76) -> 0 | AX13: =COUNTA($AB$68:$AB$76) -> 0 | AZ13: =SUM(AB68:AB76) -> 0 | BB13: =SUM(AL13+AP13+AT13+AX13) -> 0 | BD13: =SUM(AN13+AR13+AV13+AZ13) -> 0
A14: 7 | B14: 308 | C14: 여기어때 | D14: 백종훈 | F14: C | G14: 1 | H14: 15:00 | I14: 11:00 | J14: 이 | O14: 65000 | P14: 7 | AK14: 소계 | AL14: =SUM(AL10:AM11) -> 0 | AN14: =SUM(AN10:AO13) -> 0 | AP14: =SUM(AP10:AQ11) -> 0 | AR14: =SUM(AR10:AS13) -> 0 | AT14: =SUM(AT10:AU11) -> 12 | AV14: =SUM(AV10:AW13) -> 621300 | AX14: =SUM(AX10:AY11) -> 0 | AZ14: =SUM(AZ10:BA13) -> 0 | BB14: =SUM(AL14+AP14+AT14+AX14) -> 12 | BD14: =SUM(BD10:BE13) -> 621300
A15: 8 | B15: 1112 | C15: 여기어때 | D15: 박주환 | E15: 특가(랜덤) | F15: AT | G15: 1 | H15: 15:00 | I15: 11:00 | J15: 김 | O15: 60000 | P15: 8 | AK15: 어메니티 | AL15: =AL24 -> 0 | AN15: =AN24 -> 0 | AP15: =AP24 -> 2 | AR15: =AR24 -> 4000 | AX15: =AT24 -> 0 | AZ15: =AV24 -> 0 | BB15: =AX24 -> 2 | BD15: =SUM(AN15+AR15+AV15+AZ15) -> 4000
A16: 9 | B16: 1114 | C16: 야놀자 | D16: 정지민 | E16: 특가(랜덤) | F16: AT | G16: 1 | H16: 15:00 | I16: 11:00 | J16: 김 | K16: 2 | O16: 60000 | P16: 9 | BB16: 총합계 | BD16: =BD14+BD15 -> 625300
A17: 10 | P17: 10
A18: 11 | P18: 11 | AI18: 어메니티 판매현황 | AK18: 구분 | AL18: 현금 (1) | AP18: 카드 (2) | AT18: 계좌이체 (3) | AX18: 소계
A19: 12 | P19: 12 | AL19: 건수 | AN19: 금액 | AP19: 건수 | AR19: 금액 | AT19: 건수 | AV19: 금액 | AX19: 건수 | AZ19: 금액
A20: 13 | P20: 13 | AK20: 숙박 | AL20: =COUNTIF(K7:K67,1) -> 0 | AN20: =AL20*2000 -> 0 | AP20: =COUNTIF(K7:K67,2) -> 2 | AR20: =AP20*2000 -> 4000 | AT20: =COUNTIF(K8:K67,3) -> 0 | AV20: =AT20*2000 -> 0 | AX20: =SUM(AL20+AP20+AT20) -> 2 | AZ20: =SUM(AJ20+AN20+AR20+AV20) -> 4000
A21: 14 | P21: 14 | AK21: 대실 | AL21: =COUNTIF(Y7:Y67,1) -> 0 | AN21: =AL21*2000 -> 0 | AP21: =COUNTIF(Y7:Y67,2) -> 0 | AR21: =AP21*2000 -> 0 | AT21: =COUNTIF(Y8:Y67,3) -> 0 | AV21: =AT21*2000 -> 0 | AX21: =SUM(AL21+AP21+AT21) -> 0 | AZ21: =SUM(AJ21+AN21+AR21+AV21) -> 0
A22: 15 | P22: 15 | AK22: 추가 | AX22: =SUM(AL22+AP22+AT22) -> 0 | AZ22: =SUM(AJ22+AN22+AR22+AV22) -> 0
A23: 16 | P23: 16 | AX23: =SUM(AH23+AL23+AP23+AT23) -> 0 | AZ23: =SUM(AJ23+AN23+AR23+AV23) -> 0
A24: 17 | P24: 17 | AK24: 소계 | AL24: =SUM(AL20:AM23) -> 0 | AN24: =SUM(AN20:AO23) -> 0 | AP24: =SUM(AP20:AQ23) -> 2 | AR24: =SUM(AR20:AS23) -> 4000 | AT24: =SUM(AT20:AU23) -> 0 | AV24: =SUM(AV20:AW23) -> 0 | AX24: =SUM(AH24+AL24+AP24+AT24) -> 2 | AZ24: =SUM(AZ20:BA23) -> 4000
A25: 18 | P25: 18
A26: 19 | P26: 19
A27: 20 | P27: 20 | AJ27: 객실 타입 별 예약 현황
A28: 21 | P28: 21 | AJ28: 타입 | AL28: C | AN28: B | AP28: AT | AR28: AD | AS28: SD | AU28: ST | AW28: V | AX28: 특
A29: 22 | P29: 22 | AJ29: 기준수량 | AL29: 5 | AN29: 4 | AP29: 10 | AR29: 2 | AS29: 9 | AU29: 5 | AW29: 5 | AX29: 0 | AZ29: 0
A30: 23 | P30: 23 | AJ30: 예약수량 | AL30: =COUNTIF(F8:F67,"c") -> 4 | AN30: =COUNTIF(F8:F67,"b") -> 2 | AP30: =COUNTIF(F8:F67,"at") -> 2 | AR30: =COUNTIF(F8:F67,"aD") -> 0 | AS30: =COUNTIF(F8:F67,"sd") -> 1 | AU30: =COUNTIF(F8:F67,"st") -> 1 | AW30: =COUNTIF(F8:F67,"v") -> 2 | AX30: =COUNTIF(F8:F67,"PA") -> 0 | AZ30: =COUNTIF(F8:F67,"특") -> 0
A31: 24 | P31: 24 | AJ31: 잔여수량 | AL31: =AL29-AL30 -> 1 | AN31: =AN29-AN30 -> 2 | AP31: =AP29-AP30 -> 8 | AR31: =AR29-AR30 -> 2 | AS31: =AS29-AS30 -> 8 | AU31: =AU29-AU30 -> 4 | AW31: =AW29-AW30 -> 3 | AX31: =AX29-AX30 -> 0 | AZ31: =AZ29-AZ30 -> 0
A32: 25 | P32: 25 | AK32: `
A33: 26 | P33: 26
A34: 27 | P34: 27
A35: 28 | P35: 28
A36: 29 | P36: 29
A37: 30 | P37: 30
A38: 31 | P38: 31
A39: 32 | P39: 32
A40: 33 | P40: 33
...

Sheet 5
A1: 객실판매일보 | P1: 근무자 | S1: 이정경 주간/김선우 야간/황경현 팀장 | Z1: 날짜 | AA1: 45905 | AI1: 일일영업현황보고서
A2: 일매출 | C2: =AZ72 -> 2657400 | G2: 대실 | H2: =COUNTA($Z$8:$AE$67) -> 0 | M2: 숙박 | N2: =COUNTA($L$8:$O$67) -> 30 | Z2: 현금 시재 | AA2: 시작 | AB2: 371500 | AI2: 보고기준일 | AL2: ='5'!AA1 -> 45905 | AP2: 보고일자 | AS2: =AA1+1 -> 45906 | AZ2: 작성자 | BA2: =S1 -> 이정경 주간/김선우 야간/황경현 팀장
H3: =SUM(Z8:AE76)+AZ21 -> 0 | N3: =SUM(L8:O76)+AZ20 -> 2657400 | AA3: 마감 | AB3: 371500
A4: 숙 박 | N4: =SUM(COUNTIF(B8:B67,{301,302,303,305,306,307,308,309,501,502,503,505,701,702,703,705,706,707,708,709})) -> 7 | O4: =SUM(COUNTIF(B8:B67,{201,202,203,205,206,207,208,209,506,507,508,509,601,602,603,605,606,607,608,609})) -> 2 | P4: 대 실 | AF4: =SUM(COUNTIF(S8:S67,{301,302,303,305,306,307,308,309,501,502,503,505,701,702,703,705,706,707,708,709})) -> 0 | AG4: =SUM(COUNTIF(S8:S67,{201,202,203,205,206,207,208,209,506,507,508,509,601,602,603,605,606,607,608,609})) -> 0
A5: 타입 | C5: C | D5: B | E5: AT | F5: AD | G5: SD | H5: ST | I5: V | J5: 특 | N5: 남은 객실 | P5: 매출보고 | R5: 현금 | S5: 계좌 | T5: 카드 | U5: 야놀자 | W5: 여기어때 | Y5: 네이버 | AA5: 부킹 | AB5: 아고다 | AC5: 익스피디아 | AD5: 트립 | AE5: 에어 | AF5: 호텔나우 | AG5: 호텔타임
A6: 잔여수량 | C6: =AL31 -> 0 | D6: =AN31 -> 1 | E6: =AP31 -> 1 | F6: =AR31 -> 1 | G6: =AS31 -> 2 | H6: =AU31 -> 3 | I6: =AW31 -> 2 | J6: =AX31 -> 0 | N6: =C6+D6+E6+F6+G6+H6+I6+J6+K6 -> 10 | P6: =C2 -> 2657400 | R6: =AN14+AN15 -> 0 | S6: =AZ14+AZ15 -> 0 | T6: =AR14+AR15 -> 53000 | U6: =AS60 -> 1175000 | W6: =AS61 -> 960000 | Y6: =AS62 -> 65000 | AA6: =AS63 -> 0 | AB6: =AS66 -> 173400 | AC6: =AS67 -> 0 | AD6: =SUMIFS(O7:O47,C7:C47,"트립") -> 0 | AE6: =AS65 -> 0 | AF6: =AS69 -> 231000 | AG6: =AS70 -> 0
A7: 번호 | B7: 호실 | C7: 채널명 | D7: 고객명 | E7: 비고 | F7: 타입 | G7: 기간 | H7: 체크인 | I7: 체크아웃 | J7: 작성자 | K7: 비품 | L7: 현금 | M7: 카드 | N7: 계좌이체 | O7: 온라인 | P7: 번호 | Q7: 호실 | R7: 채널명 | S7: 고객명 | T7: 비고 | U7: 타입 | V7: 체크인 | W7: 체크아웃 | X7: 작성자 | Y7: 비품 | Z7: 현금 | AA7: 카드 | AB7: 계좌이체 | AE7: 온라인
A8: 1 | B8: 1112 | C8: 여기어때 | D8: 권인준 | E8: 특가(랜덤) | F8: AT | G8: 1 | H8: 15:00 | I8: 11:00 | J8: 이 | O8: 80000 | P8: 1 | AI8: 총 매 출 | AK8: 구분 | AL8: 현금 | AP8: 카드 | AT8: 온라인 | AX8: 계좌이체 | BB8: 소계
A9: 2 | B9: 1114 | C9: 여기어때 | D9: 이다은 | E9: 특가(랜덤) | F9: AT | G9: 1 | H9: 15:00 | I9: 11:00 | J9: 황 | O9: 80000 | P9: 2 | AL9: 건수 | AN9: 금액 | AP9: 건수 | AR9: 금액 | AT9: 건수 | AV9: 금액 | AX9: 건수 | AZ9: 금액 | BB9: 건수 | BD9: 금액
A10: 3 | B10: 506 | C10: 호텔나우 | D10: 김진완 | E10: C업그레이드 | F10: SD | G10: 1/2 | H10: 15:00 | I10: 11:00 | J10: 김 | O10: 231000 | P10: 3 | AK10: 숙박 | AL10: =COUNTA($L$8:$L$67) -> 0 | AN10: =SUM(L8:L67) -> 0 | AP10: =COUNT(M8:M67) -> 0 | AR10: =SUM(M8:M67) -> 0 | AT10: =COUNTA($O$8:$O$67) -> 30 | AV10: =SUM(O8:O67) -> 2604400 | AX10: =COUNTA($N$8:$N$67) -> 0 | AZ10: =SUM(N8:N67) -> 0 | BB10: =SUM(AL10+AP10+AT10+AX10) -> 30 | BD10: =SUM(AN10+AR10+AV10+AZ10) -> 2604400
A11: 4 | B11: 805 | C11: 여기어때 | D11: 김민수 | E11: C업그레이드 | F11: SD | G11: 1/2 | H11: 15:00 | I11: 11:00 | J11: 이 | O11: 210000 | P11: 4 | AK11: 대실 | AL11: =COUNTA($Z$8:$Z$67) -> 0 | AN11: =SUM(Z8:Z67) -> 0 | AP11: =COUNTA($AA$8:$AA$67) -> 0 | AR11: =SUM(AA8:AA67) -> 0 | AT11: =COUNTA($AE$8:$AE$67) -> 0 | AV11: =SUM(AE8:AE67) -> 0 | AX11: =COUNTA($AB$8:$AB$68) -> 0 | AZ11: =SUM(AB8:AB67) -> 0 | BB11: =SUM(AL11+AP11+AT11+AX11) -> 0 | BD11: =SUM(AN11+AR11+AV11+AZ11) -> 0
A12: 5 | B12: 609 | C12: 야놀자 | D12: 정경철 | E12: C업그레이드 | F12: SD | G12: 1 | H12: 15:00 | I12: 11:00 | J12: 이 | O12: 85000 | P12: 5 | AK12: 추가숙박 | AL12: =COUNTA($L$68:$L$76) -> 0 | AN12: =SUM(L68:L76) -> 0 | AP12: =COUNTA($M$68:$M$76) -> 2 | AR12: =SUM(M68:M76) -> 45000 | AT12: =COUNTA($O$68:$O$76) -> 0 | AV12: =SUM(O68:O76) -> 0 | AX12: =COUNTA($N$68:$N$76) -> 0 | AZ12: =SUM(N68:N76) -> 0 | BB12: =SUM(AL12+AP12+AT12+AX12) -> 2 | BD12: =SUM(AN12+AR12+AV12+AZ12) -> 45000
A13: 6 | B13: 1115 | C13: 여기어때 | D13: 권승욱 | E13: 특가(랜덤) | F13: AT | G13: 1 | H13: 15:00 | I13: 11:00 | J13: 황 | K13: 2 | O13: 80000 | P13: 6 | AK13: 추가대실 | AL13: =COUNTA($Z$68:$Z$76) -> 0 | AN13: =SUM(Z68:Z76) -> 0 | AP13: =COUNTA($AA$68:$AA$76) -> 0 | AR13: =SUM(AA68:AA76) -> 0 | AT13: =COUNTA($AE$68:$AE$76) -> 0 | AV13: =SUM(AE68:AE76) -> 0 | AX13: =COUNTA($AB$68:$AB$76) -> 0 | AZ13: =SUM(AB68:AB76) -> 0 | BB13: =SUM(AL13+AP13+AT13+AX13) -> 0 | BD13: =SUM(AN13+AR13+AV13+AZ13) -> 0
A14: 7 | B14: 409 | C14: 여기어때 | D14: 이웅재 | E14: C업그레이드 | F14: SD | G14: 1 | H14: 15:00 | I14: 11:00 | J14: 김 | O14: 85000 | P14: 7 | AK14: 소계 | AL14: =SUM(AL10:AM11) -> 0 | AN14: =SUM(AN10:AO13) -> 0 | AP14: =SUM(AP10:AQ11) -> 0 | AR14: =SUM(AR10:AS13) -> 45000 | AT14: =SUM(AT10:AU11) -> 30 | AV14: =SUM(AV10:AW13) -> 2604400 | AX14: =SUM(AX10:AY11) -> 0 | AZ14: =SUM(AZ10:BA13) -> 0 | BB14: =SUM(AL14+AP14+AT14+AX14) -> 30 | BD14: =SUM(BD10:BE13) -> 2649400
A15: 8 | B15: 307 | C15: 야놀자 | D15: 리센느 | F15: C | G15: 1 | H15: 15:00 | I15: 11:00 | J15: 양 | O15: 85000 | P15: 8 | AK15: 어메니티 | AL15: =AL24 -> 0 | AN15: =AN24 -> 0 | AP15: =AP24 -> 4 | AR15: =AR24 -> 8000 | AX15: =AT24 -> 0 | AZ15: =AV24 -> 0 | BB15: =AX24 -> 4 | BD15: =SUM(AN15+AR15+AV15+AZ15) -> 8000
A16: 9 | B16: 303 | C16: 야놀자 | D16: 백찬엽 | E16: 특가(랜덤) | F16: C | G16: 1 | H16: 15:00 | I16: 11:00 | J16: 이 | O16: 80000 | P16: 9 | BB16: 총합계 | BD16: =BD14+BD15 -> 2657400
A17: 10 | B17: 811 | C17: 야놀자 | D17: 남현우 | E17: 특가(랜덤) | F17: B | G17: 1 | H17: 15:00 | I17: 11:00 | J17: 양 | O17: 80000 | P17: 10
A18: 11 | B18: 305 | C18: 아고다 | D18: 임종진 | F18: C | G18: 1 | H18: 15:00 | I18: 11:00 | J18: 이 | O18: 86700 | P18: 11 | AI18: 어메니티 판매현황 | AK18: 구분 | AL18: 현금 (1) | AP18: 카드 (2) | AT18: 계좌이체 (3) | AX18: 소계
A19: 12 | B19: 401 | C19: 야놀자 | D19: 김화랑 | F19: V | G19: 1/2 | H19: 15:00 | I19: 11:00 | J19: 이 | K19: 2 | O19: 220000 | P19: 12 | AL19: 건수 | AN19: 금액 | AP19: 건수 | AR19: 금액 | AT19: 건수 | AV19: 금액 | AX19: 건수 | AZ19: 금액
A20: 13 | B20: 1107 | C20: 여기어때 | D20: 심주희 | F20: SD | G20: 1 | H20: 15:00 | I20: 11:00 | J20: 김 | O20: 95000 | P20: 13 | AK20: 숙박 | AL20: =COUNTIF(K7:K67,1) -> 0 | AN20: =AL20*2000 -> 0 | AP20: =COUNTIF(K7:K67,2) -> 4 | AR20: =AP20*2000 -> 8000 | AT20: =COUNTIF(K8:K67,3) -> 0 | AV20: =AT20*2000 -> 0 | AX20: =SUM(AL20+AP20+AT20) -> 4 | AZ20: =SUM(AJ20+AN20+AR20+AV20) -> 8000
A21: 14 | B21: 308 | C21: 여기어때 | D21: 이지원 | F21: C | G21: 1 | H21: 15:00 | I21: 11:00 | J21: 김 | O21: 80000 | P21: 14 | AK21: 대실 | AL21: =COUNTIF(Y7:Y67,1) -> 0 | AN21: =AL21*2000 -> 0 | AP21: =COUNTIF(Y7:Y67,2) -> 0 | AR21: =AP21*2000 -> 0 | AT21: =COUNTIF(Y8:Y67,3) -> 0 | AV21: =AT21*2000 -> 0 | AX21: =SUM(AL21+AP21+AT21) -> 0 | AZ21: =SUM(AJ21+AN21+AR21+AV21) -> 0
A22: 15 | B22: 309 | C22: 아고다 | D22: 김세원 | F22: C | G22: 1 | H22: 15:00 | I22: 11:00 | J22: 황 | O22: 86700 | P22: 15 | AK22: 추가 | AX22: =SUM(AL22+AP22+AT22) -> 0 | AZ22: =SUM(AJ22+AN22+AR22+AV22) -> 0
A23: 16 | B23: 1111 | C23: 여기어때 | D23: 배범진 | E23: 특가(랜덤) | F23: B | G23: 1 | H23: 15:00 | I23: 11:00 | J23: 이 | O23: 60000 | P23: 16 | AX23: =SUM(AH23+AL23+AP23+AT23) -> 0 | AZ23: =SUM(AJ23+AN23+AR23+AV23) -> 0
A24: 17 | B24: 1004 | C24: 야놀자 | D24: 송인길 | E24: C업그레이드 | F24: SD | G24: 1 | H24: 15:00 | I24: 11:00 | J24: 이 | O24: 65000 | P24: 17 | AK24: 소계 | AL24: =SUM(AL20:AM23) -> 0 | AN24: =SUM(AN20:AO23) -> 0 | AP24: =SUM(AP20:AQ23) -> 4 | AR24: =SUM(AR20:AS23) -> 8000 | AT24: =SUM(AT20:AU23) -> 0 | AV24: =SUM(AV20:AW23) -> 0 | AX24: =SUM(AH24+AL24+AP24+AT24) -> 4 | AZ24: =SUM(AZ20:BA23) -> 8000
A25: 18 | B25: 1105 | C25: 여기어때 | D25: 라니 | F25: AD | G25: 1 | H25: 15:00 | I25: 11:00 | J25: 이 | K25: 2 | O25: 70000 | P25: 18
A26: 19 | B26: 1210 | C26: 야놀자 | D26: 정우진 | F26: V | G26: 1 | H26: 15:00 | I26: 11:00 | J26: 이 | O26: 80000 | P26: 19
A27: 20 | B27: 501 | C27: 야놀자 | D27: 임영진 | F27: V | G27: 1 | H27: 15:00 | I27: 11:00 | J27: 이 | O27: 80000 | P27: 20 | AJ27: 객실 타입 별 예약 현황
A28: 21 | B28: 1116 | C28: 여기어때 | D28: 이환희 | E28: 특가(랜덤) | F28: AT | G28: 1 | H28: 15:00 | I28: 11:00 | J28: 이 | K28: 2 | O28: 60000 | P28: 21 | AJ28: 타입 | AL28: C | AN28: B | AP28: AT | AR28: AD | AS28: SD | AU28: ST | AW28: V | AX28: 특
A29: 22 | B29: 1215 | C29: 네이버 | D29: 김종운 | E29: B업그레이드 | F29: AT | G29: 1 | H29: 15:00 | I29: 11:00 | J29: 이 | O29: 65000 | P29: 22 | AJ29: 기준수량 | AL29: 5 | AN29: 4 | AP29: 10 | AR29: 2 | AS29: 9 | AU29: 5 | AW29: 5 | AX29: 0 | AZ29: 0
A30: 23 | B30: 1214 | C30: 야놀자 | D30: 이영규 | E30: 특가(랜덤) | F30: AT | G30: 1 | H30: 15:00 | I30: 11:00 | J30: 이 | O30: 60000 | P30: 23 | AJ30: 예약수량 | AL30: =COUNTIF(F8:F67,"c") -> 5 | AN30: =COUNTIF(F8:F67,"b") -> 3 | AP30: =COUNTIF(F8:F67,"at") -> 9 | AR30: =COUNTIF(F8:F67,"aD") -> 1 | AS30: =COUNTIF(F8:F67,"sd") -> 7 | AU30: =COUNTIF(F8:F67,"st") -> 2 | AW30: =COUNTIF(F8:F67,"v") -> 3 | AX30: =COUNTIF(F8:F67,"PA") -> 0 | AZ30: =COUNTIF(F8:F67,"특") -> 0
A31: 24 | B31: 1216 | C31: 야놀자 | D31: 박다솜 | E31: 특가(랜덤) | F31: AT | G31: 1 | H31: 15:00 | I31: 11:00 | J31: 이 | O31: 60000 | P31: 24 | AJ31: 잔여수량 | AL31: =AL29-AL30 -> 0 | AN31: =AN29-AN30 -> 1 | AP31: =AP29-AP30 -> 1 | AR31: =AR29-AR30 -> 1 | AS31: =AS29-AS30 -> 2 | AU31: =AU29-AU30 -> 3 | AW31: =AW29-AW30 -> 2 | AX31: =AX29-AX30 -> 0 | AZ31: =AZ29-AZ30 -> 0
A32: 25 | B32: 1206 | C32: 야놀자 | D32: 최홍석 | E32: 특가(랜덤) | F32: AT | G32: 1 | H32: 15:00 | I32: 11:00 | J32: 이 | O32: 60000 | P32: 25 | AK32: `
A33: 26 | B33: 406 | C33: 여기어때 | D33: 황은정 | E33: 특가(랜덤) | F33: ST | G33: 1 | H33: 15:00 | I33: 11:00 | J33: 김 | O33: 60000 | P33: 26
A34: 27 | B34: 809 | C34: 야놀자 | D34: 모은지 | E34: C업그레이드 | F34: SD | G34: 1/2 | H34: 15:00 | I34: 11:00 | J34: 김 | O34: 160000 | P34: 27
A35: 28 | B35: 615 | C35: 야놀자 | D35: 송정영 | E35: 특가(랜덤) | F35: AT | G35: 1 | H35: 15:00 | I35: 11:00 | J35: 김 | O35: 60000 | P35: 28
A36: 29 | P36: 29
A37: 30 | P37: 30
A38: 31 | P38: 31
A39: 32 | P39: 32
A40: 33 | P40: 33
...

Sheet 6
A1: 객실판매일보 | P1: 근무자 | S1: 이정경 주간/김선우 야간/황경현 팀장 | Z1: 날짜 | AA1: 45906 | AI1: 일일영업현황보고서
A2: 일매출 | C2: =AZ72 -> 4264152 | G2: 대실 | H2: =COUNTA($Z$8:$AE$67) -> 0 | M2: 숙박 | N2: =COUNTA($L$8:$O$67) -> 39 | Z2: 현금 시재 | AA2: 시작 | AB2: 371500 | AI2: 보고기준일 | AL2: ='6'!AA1 -> 45906 | AP2: 보고일자 | AS2: =AA1+1 -> 45907 | AZ2: 작성자 | BA2: =S1 -> 이정경 주간/김선우 야간/황경현 팀장
H3: =SUM(Z8:AE76)+AZ21 -> 0 | N3: =SUM(L8:O76)+AZ20 -> 4264152 | AA3: 마감 | AB3: 307500
A4: 숙 박 | N4: =SUM(COUNTIF(B8:B67,{301,302,303,305,306,307,308,309,501,502,503,505,701,702,703,705,706,707,708,709})) -> 9 | O4: =SUM(COUNTIF(B8:B67,{201,202,203,205,206,207,208,209,506,507,508,509,601,602,603,605,606,607,608,609})) -> 2 | P4: 대 실 | AF4: =SUM(COUNTIF(S8:S67,{301,302,303,305,306,307,308,309,501,502,503,505,701,702,703,705,706,707,708,709})) -> 0 | AG4: =SUM(COUNTIF(S8:S67,{201,202,203,205,206,207,208,209,506,507,508,509,601,602,603,605,606,607,608,609})) -> 0
A5: 타입 | C5: C | D5: B | E5: AT | F5: AD | G5: SD | H5: ST | I5: V | J5: 특 | N5: 남은 객실 | P5: 매출보고 | R5: 현금 | S5: 계좌 | T5: 카드 | U5: 야놀자 | W5: 여기어때 | Y5: 네이버 | AA5: 부킹 | AB5: 아고다 | AC5: 익스피디아 | AD5: 트립 | AE5: 에어 | AF5: 호텔나우 | AG5: 호텔타임
A6: 잔여수량 | C6: =AL31 -> 0 | D6: =AN31 -> 0 | E6: =AP31 -> 0 | F6: =AR31 -> 0 | G6: =AS31 -> 0 | H6: =AU31 -> 1 | I6: =AW31 -> 0 | J6: =AX31 -> 0 | N6: =C6+D6+E6+F6+G6+H6+I6+J6+K6 -> 1 | P6: =C2 -> 4264152 | R6: =AN14+AN15 -> 6000 | S6: =AZ14+AZ15 -> 0 | T6: =AR14+AR15 -> 296000 | U6: =AS60 -> 1125000 | W6: =AS61 -> 1110000 | Y6: =AS62 -> 95000 | AA6: =AS63 -> 0 | AB6: =AS66 -> 459000 | AC6: =AS67 -> 86422 | AD6: =SUMIFS(O7:O47,C7:C47,"트립") -> 292825 | AE6: =AS65 -> 584905 | AF6: =AS69 -> 209000 | AG6: =AS70 -> 0
A7: 번호 | B7: 호실 | C7: 채널명 | D7: 고객명 | E7: 비고 | F7: 타입 | G7: 기간 | H7: 체크인 | I7: 체크아웃 | J7: 작성자 | K7: 비품 | L7: 현금 | M7: 카드 | N7: 계좌이체 | O7: 온라인 | P7: 번호 | Q7: 호실 | R7: 채널명 | S7: 고객명 | T7: 비고 | U7: 타입 | V7: 체크인 | W7: 체크아웃 | X7: 작성자 | Y7: 비품 | Z7: 현금 | AA7: 카드 | AB7: 계좌이체 | AE7: 온라인
A8: 1 | B8: 307 | C8: 수분양자 | D8: 노현찬 | E8: 609호 | F8: C | G8: 1 | H8: 15:00 | I8: 11:00 | O8: 0 | P8: 1 | AI8: 총 매 출 | AK8: 구분 | AL8: 현금 | AP8: 카드 | AT8: 온라인 | AX8: 계좌이체 | BB8: 소계
A9: 2 | B9: 303 | C9: 트립 | D9: 김민수 | F9: C | G9: 1 | H9: 15:00 | I9: 11:00 | J9: 이 | O9: 141100 | P9: 2 | AL9: 건수 | AN9: 금액 | AP9: 건수 | AR9: 금액 | AT9: 건수 | AV9: 금액 | AX9: 건수 | AZ9: 금액 | BB9: 건수 | BD9: 금액
A10: 3 | B10: 709 | C10: 여기어때 | D10: 김보결 | F10: ST | G10: 1 | H10: 15:00 | I10: 11:00 | J10: 황 | K10: 2 | O10: 135000 | P10: 3 | AK10: 숙박 | AL10: =COUNTA($L$8:$L$67) -> 0 | AN10: =SUM(L8:L67) -> 0 | AP10: =COUNT(M8:M67) -> 1 | AR10: =SUM(M8:M67) -> 270000 | AT10: =COUNTA($O$8:$O$67) -> 38 | AV10: =SUM(O8:O67) -> 3962152 | AX10: =COUNTA($N$8:$N$67) -> 0 | AZ10: =SUM(N8:N67) -> 0 | BB10: =SUM(AL10+AP10+AT10+AX10) -> 39 | BD10: =SUM(AN10+AR10+AV10+AZ10) -> 4232152
A11: 4 | B11: 308 | C11: 트립 | D11: P/HW | E11: C업그레이드 | F11: SD | G11: 1 | H11: 15:00 | I11: 11:00 | J11: 김 | O11: 151725 | P11: 4 | AK11: 대실 | AL11: =COUNTA($Z$8:$Z$67) -> 0 | AN11: =SUM(Z8:Z67) -> 0 | AP11: =COUNTA($AA$8:$AA$67) -> 0 | AR11: =SUM(AA8:AA67) -> 0 | AT11: =COUNTA($AE$8:$AE$67) -> 0 | AV11: =SUM(AE8:AE67) -> 0 | AX11: =COUNTA($AB$8:$AB$68) -> 0 | AZ11: =SUM(AB8:AB67) -> 0 | BB11: =SUM(AL11+AP11+AT11+AX11) -> 0 | BD11: =SUM(AN11+AR11+AV11+AZ11) -> 0
A12: 5 | B12: 811 | C12: 야놀자 | D12: 권돈혁 | E12: 특가(랜덤) | F12: B | G12: 1 | H12: 15:00 | I12: 11:00 | J12: 황 | O12: 120000 | P12: 5 | AK12: 추가숙박 | AL12: =COUNTA($L$68:$L$76) -> 0 | AN12: =SUM(L68:L76) -> 0 | AP12: =COUNTA($M$68:$M$76) -> 1 | AR12: =SUM(M68:M76) -> 10000 | AT12: =COUNTA($O$68:$O$76) -> 0 | AV12: =SUM(O68:O76) -> 0 | AX12: =COUNTA($N$68:$N$76) -> 0 | AZ12: =SUM(N68:N76) -> 0 | BB12: =SUM(AL12+AP12+AT12+AX12) -> 1 | BD12: =SUM(AN12+AR12+AV12+AZ12) -> 10000
A13: 6 | B13: 309 | C13: 여기어때 | D13: 조영주 | F13: C | G13: 1 | H13: 15:00 | I13: 11:00 | J13: 김 | O13: 125000 | P13: 6 | AK13: 추가대실 | AL13: =COUNTA($Z$68:$Z$76) -> 0 | AN13: =SUM(Z68:Z76) -> 0 | AP13: =COUNTA($AA$68:$AA$76) -> 0 | AR13: =SUM(AA68:AA76) -> 0 | AT13: =COUNTA($AE$68:$AE$76) -> 0 | AV13: =SUM(AE68:AE76) -> 0 | AX13: =COUNTA($AB$68:$AB$76) -> 0 | AZ13: =SUM(AB68:AB76) -> 0 | BB13: =SUM(AL13+AP13+AT13+AX13) -> 0 | BD13: =SUM(AN13+AR13+AV13+AZ13) -> 0
A14: 7 | B14: 1004 | C14: 여기어때 | D14: 박민정 | E14: C업그레이드 | F14: SD | G14: 1 | H14: 15:00 | I14: 11:00 | J14: 이 | O14: 125000 | P14: 7 | AK14: 소계 | AL14: =SUM(AL10:AM11) -> 0 | AN14: =SUM(AN10:AO13) -> 0 | AP14: =SUM(AP10:AQ11) -> 1 | AR14: =SUM(AR10:AS13) -> 280000 | AT14: =SUM(AT10:AU11) -> 38 | AV14: =SUM(AV10:AW13) -> 3962152 | AX14: =SUM(AX10:AY11) -> 0 | AZ14: =SUM(AZ10:BA13) -> 0 | BB14: =SUM(AL14+AP14+AT14+AX14) -> 39 | BD14: =SUM(BD10:BE13) -> 4242152
A15: 8 | B15: 1105 | C15: 여기어때 | D15: 이태연 | F15: AD | G15: 1 | H15: 15:00 | I15: 11:00 | J15: 이 | K15: 2 | O15: 130000 | P15: 8 | AK15: 어메니티 | AL15: =AL24 -> 3 | AN15: =AN24 -> 6000 | AP15: =AP24 -> 8 | AR15: =AR24 -> 16000 | AX15: =AT24 -> 0 | AZ15: =AV24 -> 0 | BB15: =AX24 -> 11 | BD15: =SUM(AN15+AR15+AV15+AZ15) -> 22000
A16: 9 | B16: 902 | C16: 아고다 | D16: 유승수1 | E16: C업그레이드 | F16: SD | G16: 1 | H16: 15:00 | I16: 11:00 | J16: 양 | O16: 255000 | P16: 9 | BB16: 총합계 | BD16: =BD14+BD15 -> 4264152
A17: 10 | B17: 907 | C17: 아고다 | D17: 유승수2 | E17: C업그레이드 | F17: SD | G17: 1 | H17: 15:00 | I17: 11:00 | J17: 양 | O17: 0 | P17: 10
A18: 11 | B18: 1107 | C18: 야놀자 | D18: 김재현 | E18: C업그레이드 | F18: SD | G18: 1 | H18: 15:00 | I18: 11:00 | J18: 이 | O18: 105000 | P18: 11 | AI18: 어메니티 판매현황 | AK18: 구분 | AL18: 현금 (1) | AP18: 카드 (2) | AT18: 계좌이체 (3) | AX18: 소계
A19: 12 | B19: 615 | C19: 야놀자 | D19: 박정섭 | E19: 특가(랜덤) | F19: AT | G19: 1 | H19: 15:00 | I19: 11:00 | J19: 황 | O19: 100000 | P19: 12 | AL19: 건수 | AN19: 금액 | AP19: 건수 | AR19: 금액 | AT19: 건수 | AV19: 금액 | AX19: 건수 | AZ19: 금액
A20: 13 | B20: 305 | C20: 에어 | D20: Antoine/ | E20: Arfaoui | F20: C | G20: 1/5 | H20: 15:00 | I20: 11:00 | J20: 이 | K20: 2 | O20: 475152 | P20: 13 | AK20: 숙박 | AL20: =COUNTIF(K7:K67,1) -> 3 | AN20: =AL20*2000 -> 6000 | AP20: =COUNTIF(K7:K67,2) -> 8 | AR20: =AP20*2000 -> 16000 | AT20: =COUNTIF(K8:K67,3) -> 0 | AV20: =AT20*2000 -> 0 | AX20: =SUM(AL20+AP20+AT20) -> 11 | AZ20: =SUM(AJ20+AN20+AR20+AV20) -> 22000
A21: 14 | B21: 409 | C21: 호텔나우 | D21: 장민익 | E21: C업그레이드 | F21: SD | G21: 1 | H21: 15:00 | I21: 11:00 | J21: 이 | K21: 2 | O21: 104500 | P21: 14 | AK21: 대실 | AL21: =COUNTIF(Y7:Y67,1) -> 0 | AN21: =AL21*2000 -> 0 | AP21: =COUNTIF(Y7:Y67,2) -> 0 | AR21: =AP21*2000 -> 0 | AT21: =COUNTIF(Y8:Y67,3) -> 0 | AV21: =AT21*2000 -> 0 | AX21: =SUM(AL21+AP21+AT21) -> 0 | AZ21: =SUM(AJ21+AN21+AR21+AV21) -> 0
A22: 15 | B22: 609 | C22: 아고다 | D22: 김동환 | E22: C업그레이드 | F22: SD | G22: 1 | H22: 15:00 | I22: 11:00 | J22: 이 | O22: 96900 | P22: 15 | AK22: 추가 | AX22: =SUM(AL22+AP22+AT22) -> 0 | AZ22: =SUM(AJ22+AN22+AR22+AV22) -> 0
A23: 16 | B23: 1206 | C23: 아고다 | D23: 정경서 | E23: SD업그레이드 | F23: AD | G23: 1 | H23: 15:00 | I23: 11:00 | J23: 이 | O23: 107100 | P23: 16 | AX23: =SUM(AH23+AL23+AP23+AT23) -> 0 | AZ23: =SUM(AJ23+AN23+AR23+AV23) -> 0
A24: 17 | B24: 501 | C24: 야놀자 | D24: 김도완 | E24: SD업그레이드 | F24: V | G24: 1 | H24: 15:00 | I24: 11:00 | J24: 이 | O24: 105000 | P24: 17 | AK24: 소계 | AL24: =SUM(AL20:AM23) -> 3 | AN24: =SUM(AN20:AO23) -> 6000 | AP24: =SUM(AP20:AQ23) -> 8 | AR24: =SUM(AR20:AS23) -> 16000 | AT24: =SUM(AT20:AU23) -> 0 | AV24: =SUM(AV20:AW23) -> 0 | AX24: =SUM(AH24+AL24+AP24+AT24) -> 11 | AZ24: =SUM(AZ20:BA23) -> 22000
A25: 18 | B25: 701 | C25: 야놀자 | D25: 전호정 | F25: V | G25: 1 | H25: 15:00 | I25: 11:00 | J25: 김 | O25: 110000 | P25: 18
A26: 19 | B26: 1111 | C26: 야놀자 | D26: 이제훈 | E26: 특가(랜덤) | F26: B | G26: 1 | H26: 15:00 | I26: 11:00 | J26: 김 | O26: 90000 | P26: 19
A27: 20 | B27: 1210 | C27: 야놀자 | D27: 정우진 | F27: V | G27: 1 | H27: 15:00 | I27: 11:00 | J27: 황 | O27: 110000 | P27: 20 | AJ27: 객실 타입 별 예약 현황
A28: 21 | B28: 1011 | C28: 여기어때 | D28: 유성주 | E28: 특가(랜덤) | F28: B | G28: 1 | H28: 15:00 | I28: 11:00 | J28: 황 | K28: 2 | O28: 90000 | P28: 21 | AJ28: 타입 | AL28: C | AN28: B | AP28: AT | AR28: AD | AS28: SD | AU28: ST | AW28: V | AX28: 특
A29: 22 | B29: 713 | C29: 야놀자 | D29: 김성민 | E29: B업그레이드 | F29: AT | G29: 1 | H29: 15:00 | I29: 11:00 | J29: 황 | K29: 2 | O29: 95000 | P29: 22 | AJ29: 기준수량 | AL29: 5 | AN29: 4 | AP29: 10 | AR29: 2 | AS29: 9 | AU29: 5 | AW29: 5 | AX29: 0 | AZ29: 0
A30: 23 | B30: 1214 | C30: 호텔나우 | D30: 주원일 | E30: B업그레이드 | F30: AT | G30: 1 | H30: 15:00 | I30: 11:00 | J30: 이 | K30: 1 | O30: 104500 | P30: 23 | AJ30: 예약수량 | AL30: =COUNTIF(F8:F67,"c") -> 5 | AN30: =COUNTIF(F8:F67,"b") -> 4 | AP30: =COUNTIF(F8:F67,"at") -> 10 | AR30: =COUNTIF(F8:F67,"aD") -> 2 | AS30: =COUNTIF(F8:F67,"sd") -> 9 | AU30: =COUNTIF(F8:F67,"st") -> 4 | AW30: =COUNTIF(F8:F67,"v") -> 5 | AX30: =COUNTIF(F8:F67,"PA") -> 0 | AZ30: =COUNTIF(F8:F67,"특") -> 0
A31: 24 | B31: 1110 | C31: 현장결제 | D31: 고태원 | E31: 010-3833-8064 | F31: V | G31: 1/3 | H31: 15:00 | I31: 11:00 | J31: 이 | M31: 270000 | P31: 24 | AJ31: 잔여수량 | AL31: =AL29-AL30 -> 0 | AN31: =AN29-AN30 -> 0 | AP31: =AP29-AP30 -> 0 | AR31: =AR29-AR30 -> 0 | AS31: =AS29-AS30 -> 0 | AU31: =AU29-AU30 -> 1 | AW31: =AW29-AW30 -> 0 | AX31: =AX29-AX30 -> 0 | AZ31: =AZ29-AZ30 -> 0
A32: 25 | B32: 906 | C32: 여기어때 | D32: 권민지 | E32: AD 이슈 | F32: ST | G32: 1 | H32: 15:00 | I32: 11:00 | J32: 이 | O32: 100000 | P32: 25 | AK32: `
A33: 26 | B33: 911 | C33: 여기어때 | D33: 이예주 | E33: 특가(랜덤) | F33: B | G33: 1 | H33: 15:00 | I33: 11:00 | J33: 이 | K33: 2 | O33: 90000 | P33: 26
A34: 27 | B34: 1115 | C34: 익스피디아 | D34: 서채연 | E34: B업그레이드 | F34: AT | G34: 1 | H34: 15:00 | I34: 11:00 | J34: 황 | O34: 86422 | P34: 27
A35: 28 | B35: 1215 | C35: 야놀자 | D35: 주예진 | E35: 특가(랜덤) | F35: AT | G35: 1 | H35: 15:00 | I35: 11:00 | J35: 황 | O35: 90000 | P35: 28
A36: 29 | B36: 1112 | C36: 여기어때 | D36: 장진희 | E36: 특가(랜덤) | F36: AT | G36: 1 | H36: 15:00 | I36: 11:00 | J36: 이 | K36: 2 | O36: 90000 | P36: 29
A37: 30 | B37: 1116 | C37: 야놀자 | D37: 이선화 | F37: AT | G37: 1 | H37: 15:00 | I37: 11:00 | J37: 이 | O37: 100000 | P37: 30
A38: 31 | B38: 1216 | C38: 여기어때 | D38: 임수아 | E38: B업그레이드 | F38: AT | G38: 1 | H38: 15:00 | I38: 11:00 | J38: 황 | O38: 95000 | P38: 31
A39: 32 | B39: 1114 | C39: 에어 | D39: 최강 | E39: B업그레이드 | F39: AT | G39: 1 | H39: 15:00 | I39: 11:00 | J39: 이 | O39: 109753 | P39: 32
A40: 33 | B40: 715 | C40: 네이버 | D40: 김상완 | E40: B업그레이드 | F40: AT | G40: 1 | H40: 15:00 | I40: 11:00 | J40: 이 | K40: 1 | O40: 95000 | P40: 33
...

Sheet 7
A1: 객실판매일보 | P1: 근무자 | S1: 이정경 주간/김선우 야간/황경현 팀장 | Z1: 날짜 | AA1: 45907 | AI1: 일일영업현황보고서
A2: 일매출 | C2: =AZ72 -> 1374200 | G2: 대실 | H2: =COUNTA($Z$8:$AE$67) -> 0 | M2: 숙박 | N2: =COUNTA($L$8:$O$67) -> 16 | Z2: 현금 시재 | AA2: 시작 | AB2: 307500 | AI2: 보고기준일 | AL2: ='7'!AA1 -> 45907 | AP2: 보고일자 | AS2: =AA1+1 -> 45908 | AZ2: 작성자 | BA2: =S1 -> 이정경 주간/김선우 야간/황경현 팀장
H3: =SUM(Z8:AE76)+AZ21 -> 0 | N3: =SUM(L8:O76)+AZ20 -> 1374200 | AA3: 마감 | AB3: 309500
A4: 숙 박 | N4: =SUM(COUNTIF(B8:B67,{301,302,303,305,306,307,308,309,501,502,503,505,701,702,703,705,706,707,708,709})) -> 5 | O4: =SUM(COUNTIF(B8:B67,{201,202,203,205,206,207,208,209,506,507,508,509,601,602,603,605,606,607,608,609})) -> 2 | P4: 대 실 | AF4: =SUM(COUNTIF(S8:S67,{301,302,303,305,306,307,308,309,501,502,503,505,701,702,703,705,706,707,708,709})) -> 0 | AG4: =SUM(COUNTIF(S8:S67,{201,202,203,205,206,207,208,209,506,507,508,509,601,602,603,605,606,607,608,609})) -> 0
A5: 타입 | C5: C | D5: B | E5: AT | F5: AD | G5: SD | H5: ST | I5: V | J5: 특 | N5: 남은 객실 | P5: 매출보고 | R5: 현금 | S5: 계좌 | T5: 카드 | U5: 야놀자 | W5: 여기어때 | Y5: 네이버 | AA5: 부킹 | AB5: 아고다 | AC5: 익스피디아 | AD5: 트립 | AE5: 에어 | AF5: 호텔나우 | AG5: 호텔타임
A6: 잔여수량 | C6: =AL31 -> 0 | D6: =AN31 -> 3 | E6: =AP31 -> 9 | F6: =AR31 -> 1 | G6: =AS31 -> 4 | H6: =AU31 -> 5 | I6: =AW31 -> 2 | J6: =AX31 -> 0 | N6: =C6+D6+E6+F6+G6+H6+I6+J6+K6 -> 24 | P6: =C2 -> 1374200 | R6: =AN14+AN15 -> 2000 | S6: =AZ14+AZ15 -> 0 | T6: =AR14+AR15 -> 182000 | U6: =AS60 -> 185000 | W6: =AS61 -> 740000 | Y6: =AS62 -> 0 | AA6: =AS63 -> 0 | AB6: =AS66 -> 265200 | AC6: =AS67 -> 0 | AD6: =SUMIFS(O7:O47,C7:C47,"트립") -> 0 | AE6: =AS65 -> 0 | AF6: =AS69 -> 0 | AG6: =AS70 -> 0
A7: 번호 | B7: 호실 | C7: 채널명 | D7: 고객명 | E7: 비고 | F7: 타입 | G7: 기간 | H7: 체크인 | I7: 체크아웃 | J7: 작성자 | K7: 비품 | L7: 현금 | M7: 카드 | N7: 계좌이체 | O7: 온라인 | P7: 번호 | Q7: 호실 | R7: 채널명 | S7: 고객명 | T7: 비고 | U7: 타입 | V7: 체크인 | W7: 체크아웃 | X7: 작성자 | Y7: 비품 | Z7: 현금 | AA7: 카드 | AB7: 계좌이체 | AE7: 온라인
A8: 1 | B8: 308 | C8: 여기어때 | D8: 이성빈 | E8: 특가(랜덤) | F8: C | G8: 1/4 | H8: 15:00 | I8: 11:00 | J8: 이 | O8: 240000 | P8: 1 | AI8: 총 매 출 | AK8: 구분 | AL8: 현금 | AP8: 카드 | AT8: 온라인 | AX8: 계좌이체 | BB8: 소계
A9: 2 | B9: 805 | C9: 여기어때 | D9: 배민환 | E9: C업그레이드 | F9: SD | G9: 1 | H9: 15:00 | I9: 11:00 | J9: 이 | O9: 65000 | P9: 2 | AL9: 건수 | AN9: 금액 | AP9: 건수 | AR9: 금액 | AT9: 건수 | AV9: 금액 | AX9: 건수 | AZ9: 금액 | BB9: 건수 | BD9: 금액
A10: 3 | B10: 401 | C10: 야놀자 | D10: 권병지 | E10: C업그레이드 | F10: V | G10: 1 | H10: 15:00 | I10: 11:00 | J10: 김 | O10: 65000 | P10: 3 | AK10: 숙박 | AL10: =COUNTA($L$8:$L$67) -> 0 | AN10: =SUM(L8:L67) -> 0 | AP10: =COUNT(M8:M67) -> 1 | AR10: =SUM(M8:M67) -> 80000 | AT10: =COUNTA($O$8:$O$67) -> 15 | AV10: =SUM(O8:O67) -> 1190200 | AX10: =COUNTA($N$8:$N$67) -> 0 | AZ10: =SUM(N8:N67) -> 0 | BB10: =SUM(AL10+AP10+AT10+AX10) -> 16 | BD10: =SUM(AN10+AR10+AV10+AZ10) -> 1270200
A11: 4 | B11: 609 | C11: 여기어때 | D11: 김민정 | E11: C업그레이드 | F11: SD | G11: 1/2 | H11: 15:00 | I11: 11:00 | J11: 김 | O11: 130000 | P11: 4 | AK11: 대실 | AL11: =COUNTA($Z$8:$Z$67) -> 0 | AN11: =SUM(Z8:Z67) -> 0 | AP11: =COUNTA($AA$8:$AA$67) -> 0 | AR11: =SUM(AA8:AA67) -> 0 | AT11: =COUNTA($AE$8:$AE$67) -> 0 | AV11: =SUM(AE8:AE67) -> 0 | AX11: =COUNTA($AB$8:$AB$68) -> 0 | AZ11: =SUM(AB8:AB67) -> 0 | BB11: =SUM(AL11+AP11+AT11+AX11) -> 0 | BD11: =SUM(AN11+AR11+AV11+AZ11) -> 0
A12: 5 | B12: 1214 | C12: 야놀자 | D12: 김성진 | E12: 특가(랜덤) | F12: AT | G12: 1 | H12: 15:00 | I12: 11:00 | J12: 이 | O12: 60000 | P12: 5 | AK12: 추가숙박 | AL12: =COUNTA($L$68:$L$76) -> 0 | AN12: =SUM(L68:L76) -> 0 | AP12: =COUNTA($M$68:$M$76) -> 4 | AR12: =SUM(M68:M76) -> 100000 | AT12: =COUNTA($O$68:$O$76) -> 0 | AV12: =SUM(O68:O76) -> 0 | AX12: =COUNTA($N$68:$N$76) -> 0 | AZ12: =SUM(N68:N76) -> 0 | BB12: =SUM(AL12+AP12+AT12+AX12) -> 4 | BD12: =SUM(AN12+AR12+AV12+AZ12) -> 100000
A13: 6 | B13: 307 | C13: 아고다 | D13: 이옥희 | F13: C | G13: 1/2 | H13: 15:00 | I13: 11:00 | J13: 이 | O13: 132600 | P13: 6 | AK13: 추가대실 | AL13: =COUNTA($Z$68:$Z$76) -> 0 | AN13: =SUM(Z68:Z76) -> 0 | AP13: =COUNTA($AA$68:$AA$76) -> 0 | AR13: =SUM(AA68:AA76) -> 0 | AT13: =COUNTA($AE$68:$AE$76) -> 0 | AV13: =SUM(AE68:AE76) -> 0 | AX13: =COUNTA($AB$68:$AB$76) -> 0 | AZ13: =SUM(AB68:AB76) -> 0 | BB13: =SUM(AL13+AP13+AT13+AX13) -> 0 | BD13: =SUM(AN13+AR13+AV13+AZ13) -> 0
A14: 7 | B14: 506 | C14: 야놀자 | D14: 김민찬 | E14: 특가(랜덤) | F14: SD | G14: 1 | H14: 15:00 | I14: 11:00 | J14: 김 | K14: 2 | O14: 60000 | P14: 7 | AK14: 소계 | AL14: =SUM(AL10:AM11) -> 0 | AN14: =SUM(AN10:AO13) -> 0 | AP14: =SUM(AP10:AQ11) -> 1 | AR14: =SUM(AR10:AS13) -> 180000 | AT14: =SUM(AT10:AU11) -> 15 | AV14: =SUM(AV10:AW13) -> 1190200 | AX14: =SUM(AX10:AY11) -> 0 | AZ14: =SUM(AZ10:BA13) -> 0 | BB14: =SUM(AL14+AP14+AT14+AX14) -> 16 | BD14: =SUM(BD10:BE13) -> 1370200
A15: 8 | B15: 303 | C15: 여기어때 | D15: 이채현 | E15: 특가(랜덤) | F15: C | G15: 1 | H15: 15:00 | I15: 11:00 | J15: 김 | O15: 60000 | P15: 8 | AK15: 어메니티 | AL15: =AL24 -> 1 | AN15: =AN24 -> 2000 | AP15: =AP24 -> 1 | AR15: =AR24 -> 2000 | AX15: =AT24 -> 0 | AZ15: =AV24 -> 0 | BB15: =AX24 -> 2 | BD15: =SUM(AN15+AR15+AV15+AZ15) -> 4000
A16: 9 | B16: 811 | C16: 여기어때 | D16: 이재희 | E16: 특가(랜덤) | F16: B | G16: 1 | H16: 15:00 | I16: 11:00 | J16: 김 | O16: 60000 | P16: 9 | BB16: 총합계 | BD16: =BD14+BD15 -> 1374200
A17: 10 | B17: 1210 | C17: 숙박연장 | D17: 정우진 | F17: V | G17: 1 | H17: 15:00 | I17: 11:00 | J17: 황 | M17: 80000 | P17: 10
A18: 11 | B18: 809 | C18: 여기어때 | D18: 양재만 | E18: C업그레이드 | F18: SD | G18: 1 | H18: 15:00 | I18: 11:00 | J18: 이 | O18: 65000 | P18: 11 | AI18: 어메니티 판매현황 | AK18: 구분 | AL18: 현금 (1) | AP18: 카드 (2) | AT18: 계좌이체 (3) | AX18: 소계
A19: 12 | B19: 309 | C19: 여기어때 | D19: 조은서 | E19: 특가(랜덤) | F19: C | G19: 1 | H19: 15:00 | I19: 11:00 | J19: 이 | O19: 60000 | P19: 12 | AL19: 건수 | AN19: 금액 | AP19: 건수 | AR19: 금액 | AT19: 건수 | AV19: 금액 | AX19: 건수 | AZ19: 금액
A20: 13 | B20: 409 | C20: 아고다 | D20: 권한주 | E20: C업그레이드 | F20: SD | G20: 1/2 | H20: 15:00 | I20: 11:00 | J20: 이 | K20: 1 | O20: 132600 | P20: 13 | AK20: 숙박 | AL20: =COUNTIF(K7:K67,1) -> 1 | AN20: =AL20*2000 -> 2000 | AP20: =COUNTIF(K7:K67,2) -> 1 | AR20: =AP20*2000 -> 2000 | AT20: =COUNTIF(K8:K67,3) -> 0 | AV20: =AT20*2000 -> 0 | AX20: =SUM(AL20+AP20+AT20) -> 2 | AZ20: =SUM(AJ20+AN20+AR20+AV20) -> 4000
A21: 14 | B21: 1206 | C21: 여기어때 | D21: 써니문 | E21: 특가(랜덤) | F21: AD | G21: 1 | H21: 15:00 | I21: 11:00 | J21: 이 | O21: 60000 | P21: 14 | AK21: 대실 | AL21: =COUNTIF(Y7:Y67,1) -> 0 | AN21: =AL21*2000 -> 0 | AP21: =COUNTIF(Y7:Y67,2) -> 0 | AR21: =AP21*2000 -> 0 | AT21: =COUNTIF(Y8:Y67,3) -> 0 | AV21: =AT21*2000 -> 0 | AX21: =SUM(AL21+AP21+AT21) -> 0 | AZ21: =SUM(AJ21+AN21+AR21+AV21) -> 0
A22: 15 | P22: 15 | AK22: 추가 | AX22: =SUM(AL22+AP22+AT22) -> 0 | AZ22: =SUM(AJ22+AN22+AR22+AV22) -> 0
A23: 16 | P23: 16 | AX23: =SUM(AH23+AL23+AP23+AT23) -> 0 | AZ23: =SUM(AJ23+AN23+AR23+AV23) -> 0
A24: 17 | P24: 17 | AK24: 소계 | AL24: =SUM(AL20:AM23) -> 1 | AN24: =SUM(AN20:AO23) -> 2000 | AP24: =SUM(AP20:AQ23) -> 1 | AR24: =SUM(AR20:AS23) -> 2000 | AT24: =SUM(AT20:AU23) -> 0 | AV24: =SUM(AV20:AW23) -> 0 | AX24: =SUM(AH24+AL24+AP24+AT24) -> 2 | AZ24: =SUM(AZ20:BA23) -> 4000
A25: 18 | P25: 18
A26: 19 | P26: 19
A27: 20 | P27: 20 | AJ27: 객실 타입 별 예약 현황
A28: 21 | P28: 21 | AJ28: 타입 | AL28: C | AN28: B | AP28: AT | AR28: AD | AS28: SD | AU28: ST | AW28: V | AX28: 특
A29: 22 | P29: 22 | AJ29: 기준수량 | AL29: 5 | AN29: 4 | AP29: 10 | AR29: 2 | AS29: 9 | AU29: 5 | AW29: 5 | AX29: 0 | AZ29: 0
A30: 23 | P30: 23 | AJ30: 예약수량 | AL30: =COUNTIF(F8:F67,"c") -> 5 | AN30: =COUNTIF(F8:F67,"b") -> 1 | AP30: =COUNTIF(F8:F67,"at") -> 1 | AR30: =COUNTIF(F8:F67,"aD") -> 1 | AS30: =COUNTIF(F8:F67,"sd") -> 5 | AU30: =COUNTIF(F8:F67,"st") -> 0 | AW30: =COUNTIF(F8:F67,"v") -> 3 | AX30: =COUNTIF(F8:F67,"PA") -> 0 | AZ30: =COUNTIF(F8:F67,"특") -> 0
A31: 24 | P31: 24 | AJ31: 잔여수량 | AL31: =AL29-AL30 -> 0 | AN31: =AN29-AN30 -> 3 | AP31: =AP29-AP30 -> 9 | AR31: =AR29-AR30 -> 1 | AS31: =AS29-AS30 -> 4 | AU31: =AU29-AU30 -> 5 | AW31: =AW29-AW30 -> 2 | AX31: =AX29-AX30 -> 0 | AZ31: =AZ29-AZ30 -> 0
A32: 25 | P32: 25 | AK32: `
A33: 26 | P33: 26
A34: 27 | P34: 27
A35: 28 | P35: 28
A36: 29 | P36: 29
A37: 30 | P37: 30
A38: 31 | P38: 31
A39: 32 | P39: 32
A40: 33 | P40: 33
...

Sheet 8
A1: 객실판매일보 | P1: 근무자 | S1: 이정경 주간/김선우 야간/황경현 팀장 | Z1: 날짜 | AA1: 45908 | AI1: 일일영업현황보고서
A2: 일매출 | C2: =AZ72 -> 1008750 | G2: 대실 | H2: =COUNTA($Z$8:$AE$67) -> 0 | M2: 숙박 | N2: =COUNTA($L$8:$O$67) -> 19 | Z2: 현금 시재 | AA2: 시작 | AB2: 309500 | AI2: 보고기준일 | AL2: ='8'!AA1 -> 45908 | AP2: 보고일자 | AS2: =AA1+1 -> 45909 | AZ2: 작성자 | BA2: =S1 -> 이정경 주간/김선우 야간/황경현 팀장
H3: =SUM(Z8:AE76)+AZ21 -> 0 | N3: =SUM(L8:O76)+AZ20 -> 1008750 | AA3: 마감 | AB3: 309500
A4: 숙 박 | N4: =SUM(COUNTIF(B8:B67,{301,302,303,305,306,307,308,309,501,502,503,505,701,702,703,705,706,707,708,709})) -> 7 | O4: =SUM(COUNTIF(B8:B67,{201,202,203,205,206,207,208,209,506,507,508,509,601,602,603,605,606,607,608,609})) -> 1 | P4: 대 실 | AF4: =SUM(COUNTIF(S8:S67,{301,302,303,305,306,307,308,309,501,502,503,505,701,702,703,705,706,707,708,709})) -> 0 | AG4: =SUM(COUNTIF(S8:S67,{201,202,203,205,206,207,208,209,506,507,508,509,601,602,603,605,606,607,608,609})) -> 0
